<?xml version="1.0" ?>
<robot name="inspire_hand_left">
  <link name="base_link">
    <visual>
      <origin xyz="0 0 0" rpy="0 0 0"/>
      <geometry>
        <mesh filename="package://inspire_hand_description/meshes/left/full_hand.stl"/>
      </geometry>
    </visual>
    <collision>
      <origin xyz="0 0 0" rpy="0 0 0"/>
      <geometry>
        <box size="0.1 0.08 0.03"/>
      </geometry>
    </collision>
    <inertial>
      <mass value="0.2"/>
      <origin xyz="0 0 0" rpy="0 0 0"/>
      <inertia ixx="2e-07" ixy="0" ixz="0" iyy="2e-07" iyz="0" izz="2e-07"/>
    </inertial>
  </link>
  <link name="little_1_link">
    <visual>
      <origin xyz="0 0 0" rpy="0 0 0"/>
      <geometry>
        <box size="0.01 0.008 0.006"/>
      </geometry>
      <material name="finger_color">
        <color rgba="0.8 0.6 0.5 1.0"/>
      </material>
    </visual>
    <collision>
      <origin xyz="0 0 0" rpy="0 0 0"/>
      <geometry>
        <box size="0.01 0.008 0.006"/>
      </geometry>
    </collision>
    <inertial>
      <mass value="0.01"/>
      <origin xyz="0 0 0" rpy="0 0 0"/>
      <inertia ixx="1e-08" ixy="0" ixz="0" iyy="1e-08" iyz="0" izz="1e-08"/>
    </inertial>
  </link>
  <link name="little_2_link">
    <visual>
      <origin xyz="0 0 0" rpy="0 0 0"/>
      <geometry>
        <box size="0.01 0.008 0.006"/>
      </geometry>
      <material name="finger_color">
        <color rgba="0.8 0.6 0.5 1.0"/>
      </material>
    </visual>
    <collision>
      <origin xyz="0 0 0" rpy="0 0 0"/>
      <geometry>
        <box size="0.01 0.008 0.006"/>
      </geometry>
    </collision>
    <inertial>
      <mass value="0.01"/>
      <origin xyz="0 0 0" rpy="0 0 0"/>
      <inertia ixx="1e-08" ixy="0" ixz="0" iyy="1e-08" iyz="0" izz="1e-08"/>
    </inertial>
  </link>
  <link name="little_3_link">
    <visual>
      <origin xyz="0 0 0" rpy="0 0 0"/>
      <geometry>
        <box size="0.01 0.008 0.006"/>
      </geometry>
      <material name="finger_color">
        <color rgba="0.8 0.6 0.5 1.0"/>
      </material>
    </visual>
    <collision>
      <origin xyz="0 0 0" rpy="0 0 0"/>
      <geometry>
        <box size="0.01 0.008 0.006"/>
      </geometry>
    </collision>
    <inertial>
      <mass value="0.01"/>
      <origin xyz="0 0 0" rpy="0 0 0"/>
      <inertia ixx="1e-08" ixy="0" ixz="0" iyy="1e-08" iyz="0" izz="1e-08"/>
    </inertial>
  </link>
  <link name="ring_1_link">
    <visual>
      <origin xyz="0 0 0" rpy="0 0 0"/>
      <geometry>
        <box size="0.01 0.008 0.006"/>
      </geometry>
      <material name="finger_color">
        <color rgba="0.8 0.6 0.5 1.0"/>
      </material>
    </visual>
    <collision>
      <origin xyz="0 0 0" rpy="0 0 0"/>
      <geometry>
        <box size="0.01 0.008 0.006"/>
      </geometry>
    </collision>
    <inertial>
      <mass value="0.01"/>
      <origin xyz="0 0 0" rpy="0 0 0"/>
      <inertia ixx="1e-08" ixy="0" ixz="0" iyy="1e-08" iyz="0" izz="1e-08"/>
    </inertial>
  </link>
  <link name="ring_2_link">
    <visual>
      <origin xyz="0 0 0" rpy="0 0 0"/>
      <geometry>
        <box size="0.01 0.008 0.006"/>
      </geometry>
      <material name="finger_color">
        <color rgba="0.8 0.6 0.5 1.0"/>
      </material>
    </visual>
    <collision>
      <origin xyz="0 0 0" rpy="0 0 0"/>
      <geometry>
        <box size="0.01 0.008 0.006"/>
      </geometry>
    </collision>
    <inertial>
      <mass value="0.01"/>
      <origin xyz="0 0 0" rpy="0 0 0"/>
      <inertia ixx="1e-08" ixy="0" ixz="0" iyy="1e-08" iyz="0" izz="1e-08"/>
    </inertial>
  </link>
  <link name="ring_3_link">
    <visual>
      <origin xyz="0 0 0" rpy="0 0 0"/>
      <geometry>
        <box size="0.01 0.008 0.006"/>
      </geometry>
      <material name="finger_color">
        <color rgba="0.8 0.6 0.5 1.0"/>
      </material>
    </visual>
    <collision>
      <origin xyz="0 0 0" rpy="0 0 0"/>
      <geometry>
        <box size="0.01 0.008 0.006"/>
      </geometry>
    </collision>
    <inertial>
      <mass value="0.01"/>
      <origin xyz="0 0 0" rpy="0 0 0"/>
      <inertia ixx="1e-08" ixy="0" ixz="0" iyy="1e-08" iyz="0" izz="1e-08"/>
    </inertial>
  </link>
  <link name="middle_1_link">
    <visual>
      <origin xyz="0 0 0" rpy="0 0 0"/>
      <geometry>
        <box size="0.01 0.008 0.006"/>
      </geometry>
      <material name="finger_color">
        <color rgba="0.8 0.6 0.5 1.0"/>
      </material>
    </visual>
    <collision>
      <origin xyz="0 0 0" rpy="0 0 0"/>
      <geometry>
        <box size="0.01 0.008 0.006"/>
      </geometry>
    </collision>
    <inertial>
      <mass value="0.01"/>
      <origin xyz="0 0 0" rpy="0 0 0"/>
      <inertia ixx="1e-08" ixy="0" ixz="0" iyy="1e-08" iyz="0" izz="1e-08"/>
    </inertial>
  </link>
  <link name="middle_2_link">
    <visual>
      <origin xyz="0 0 0" rpy="0 0 0"/>
      <geometry>
        <box size="0.01 0.008 0.006"/>
      </geometry>
      <material name="finger_color">
        <color rgba="0.8 0.6 0.5 1.0"/>
      </material>
    </visual>
    <collision>
      <origin xyz="0 0 0" rpy="0 0 0"/>
      <geometry>
        <box size="0.01 0.008 0.006"/>
      </geometry>
    </collision>
    <inertial>
      <mass value="0.01"/>
      <origin xyz="0 0 0" rpy="0 0 0"/>
      <inertia ixx="1e-08" ixy="0" ixz="0" iyy="1e-08" iyz="0" izz="1e-08"/>
    </inertial>
  </link>
  <link name="middle_3_link">
    <visual>
      <origin xyz="0 0 0" rpy="0 0 0"/>
      <geometry>
        <box size="0.01 0.008 0.006"/>
      </geometry>
      <material name="finger_color">
        <color rgba="0.8 0.6 0.5 1.0"/>
      </material>
    </visual>
    <collision>
      <origin xyz="0 0 0" rpy="0 0 0"/>
      <geometry>
        <box size="0.01 0.008 0.006"/>
      </geometry>
    </collision>
    <inertial>
      <mass value="0.01"/>
      <origin xyz="0 0 0" rpy="0 0 0"/>
      <inertia ixx="1e-08" ixy="0" ixz="0" iyy="1e-08" iyz="0" izz="1e-08"/>
    </inertial>
  </link>
  <link name="index_1_link">
    <visual>
      <origin xyz="0 0 0" rpy="0 0 0"/>
      <geometry>
        <box size="0.01 0.008 0.006"/>
      </geometry>
      <material name="finger_color">
        <color rgba="0.8 0.6 0.5 1.0"/>
      </material>
    </visual>
    <collision>
      <origin xyz="0 0 0" rpy="0 0 0"/>
      <geometry>
        <box size="0.01 0.008 0.006"/>
      </geometry>
    </collision>
    <inertial>
      <mass value="0.01"/>
      <origin xyz="0 0 0" rpy="0 0 0"/>
      <inertia ixx="1e-08" ixy="0" ixz="0" iyy="1e-08" iyz="0" izz="1e-08"/>
    </inertial>
  </link>
  <link name="index_2_link">
    <visual>
      <origin xyz="0 0 0" rpy="0 0 0"/>
      <geometry>
        <box size="0.01 0.008 0.006"/>
      </geometry>
      <material name="finger_color">
        <color rgba="0.8 0.6 0.5 1.0"/>
      </material>
    </visual>
    <collision>
      <origin xyz="0 0 0" rpy="0 0 0"/>
      <geometry>
        <box size="0.01 0.008 0.006"/>
      </geometry>
    </collision>
    <inertial>
      <mass value="0.01"/>
      <origin xyz="0 0 0" rpy="0 0 0"/>
      <inertia ixx="1e-08" ixy="0" ixz="0" iyy="1e-08" iyz="0" izz="1e-08"/>
    </inertial>
  </link>
  <link name="index_3_link">
    <visual>
      <origin xyz="0 0 0" rpy="0 0 0"/>
      <geometry>
        <box size="0.01 0.008 0.006"/>
      </geometry>
      <material name="finger_color">
        <color rgba="0.8 0.6 0.5 1.0"/>
      </material>
    </visual>
    <collision>
      <origin xyz="0 0 0" rpy="0 0 0"/>
      <geometry>
        <box size="0.01 0.008 0.006"/>
      </geometry>
    </collision>
    <inertial>
      <mass value="0.01"/>
      <origin xyz="0 0 0" rpy="0 0 0"/>
      <inertia ixx="1e-08" ixy="0" ixz="0" iyy="1e-08" iyz="0" izz="1e-08"/>
    </inertial>
  </link>
  <link name="thumb_1_link">
    <visual>
      <origin xyz="0 0 0" rpy="0 0 0"/>
      <geometry>
        <box size="0.012 0.01 0.008"/>
      </geometry>
      <material name="finger_color">
        <color rgba="0.8 0.6 0.5 1.0"/>
      </material>
    </visual>
    <collision>
      <origin xyz="0 0 0" rpy="0 0 0"/>
      <geometry>
        <box size="0.012 0.01 0.008"/>
      </geometry>
    </collision>
    <inertial>
      <mass value="0.01"/>
      <origin xyz="0 0 0" rpy="0 0 0"/>
      <inertia ixx="1e-08" ixy="0" ixz="0" iyy="1e-08" iyz="0" izz="1e-08"/>
    </inertial>
  </link>
  <link name="thumb_2_link">
    <visual>
      <origin xyz="0 0 0" rpy="0 0 0"/>
      <geometry>
        <box size="0.012 0.01 0.008"/>
      </geometry>
      <material name="finger_color">
        <color rgba="0.8 0.6 0.5 1.0"/>
      </material>
    </visual>
    <collision>
      <origin xyz="0 0 0" rpy="0 0 0"/>
      <geometry>
        <box size="0.012 0.01 0.008"/>
      </geometry>
    </collision>
    <inertial>
      <mass value="0.01"/>
      <origin xyz="0 0 0" rpy="0 0 0"/>
      <inertia ixx="1e-08" ixy="0" ixz="0" iyy="1e-08" iyz="0" izz="1e-08"/>
    </inertial>
  </link>
  <link name="thumb_3_link">
    <visual>
      <origin xyz="0 0 0" rpy="0 0 0"/>
      <geometry>
        <box size="0.012 0.01 0.008"/>
      </geometry>
      <material name="finger_color">
        <color rgba="0.8 0.6 0.5 1.0"/>
      </material>
    </visual>
    <collision>
      <origin xyz="0 0 0" rpy="0 0 0"/>
      <geometry>
        <box size="0.012 0.01 0.008"/>
      </geometry>
    </collision>
    <inertial>
      <mass value="0.01"/>
      <origin xyz="0 0 0" rpy="0 0 0"/>
      <inertia ixx="1e-08" ixy="0" ixz="0" iyy="1e-08" iyz="0" izz="1e-08"/>
    </inertial>
  </link>
  <link name="thumb_4_link">
    <visual>
      <origin xyz="0 0 0" rpy="0 0 0"/>
      <geometry>
        <box size="0.012 0.01 0.008"/>
      </geometry>
      <material name="finger_color">
        <color rgba="0.8 0.6 0.5 1.0"/>
      </material>
    </visual>
    <collision>
      <origin xyz="0 0 0" rpy="0 0 0"/>
      <geometry>
        <box size="0.012 0.01 0.008"/>
      </geometry>
    </collision>
    <inertial>
      <mass value="0.01"/>
      <origin xyz="0 0 0" rpy="0 0 0"/>
      <inertia ixx="1e-08" ixy="0" ixz="0" iyy="1e-08" iyz="0" izz="1e-08"/>
    </inertial>
  </link>
  <joint name="little_1_joint" type="revolute">
    <parent link="base_link"/>
    <child link="little_1_link"/>
    <origin xyz="-0.08 -0.02 0.01" rpy="0 0 0"/>
    <axis xyz="0 1 0"/>
    <limit lower="0.0" upper="1.333" effort="1.0" velocity="1.0"/>
  </joint>
  <joint name="little_2_joint" type="revolute">
    <parent link="little_1_link"/>
    <child link="little_2_link"/>
    <origin xyz="0.025 0 0" rpy="0 0 0"/>
    <axis xyz="0 1 0"/>
    <limit lower="0.0" upper="1.4888276999999999" effort="1.0" velocity="1.0"/>
    <mimic joint="little_1_joint" multiplier="1.1169" offset="0.0"/>
  </joint>
  <joint name="little_3_joint" type="fixed">
    <parent link="little_2_link"/>
    <child link="little_3_link"/>
    <origin xyz="0.02 0 0" rpy="0 0 0"/>
  </joint>
  <joint name="ring_1_joint" type="revolute">
    <parent link="base_link"/>
    <child link="ring_1_link"/>
    <origin xyz="-0.085 0.0 0.01" rpy="0 0 0"/>
    <axis xyz="0 1 0"/>
    <limit lower="0.0" upper="1.333" effort="1.0" velocity="1.0"/>
  </joint>
  <joint name="ring_2_joint" type="revolute">
    <parent link="ring_1_link"/>
    <child link="ring_2_link"/>
    <origin xyz="0.03 0 0" rpy="0 0 0"/>
    <axis xyz="0 1 0"/>
    <limit lower="0.0" upper="1.4888276999999999" effort="1.0" velocity="1.0"/>
    <mimic joint="ring_1_joint" multiplier="1.1169" offset="0.0"/>
  </joint>
  <joint name="ring_3_joint" type="fixed">
    <parent link="ring_2_link"/>
    <child link="ring_3_link"/>
    <origin xyz="0.022 0 0" rpy="0 0 0"/>
  </joint>
  <joint name="middle_1_joint" type="revolute">
    <parent link="base_link"/>
    <child link="middle_1_link"/>
    <origin xyz="-0.085 0.02 0.01" rpy="0 0 0"/>
    <axis xyz="0 1 0"/>
    <limit lower="0.0" upper="1.333" effort="1.0" velocity="1.0"/>
  </joint>
  <joint name="middle_2_joint" type="revolute">
    <parent link="middle_1_link"/>
    <child link="middle_2_link"/>
    <origin xyz="0.035 0 0" rpy="0 0 0"/>
    <axis xyz="0 1 0"/>
    <limit lower="0.0" upper="1.4888276999999999" effort="1.0" velocity="1.0"/>
    <mimic joint="middle_1_joint" multiplier="1.1169" offset="0.0"/>
  </joint>
  <joint name="middle_3_joint" type="fixed">
    <parent link="middle_2_link"/>
    <child link="middle_3_link"/>
    <origin xyz="0.025 0 0" rpy="0 0 0"/>
  </joint>
  <joint name="index_1_joint" type="revolute">
    <parent link="base_link"/>
    <child link="index_1_link"/>
    <origin xyz="-0.08 0.04 0.01" rpy="0 0 0"/>
    <axis xyz="0 1 0"/>
    <limit lower="0.0" upper="1.333" effort="1.0" velocity="1.0"/>
  </joint>
  <joint name="index_2_joint" type="revolute">
    <parent link="index_1_link"/>
    <child link="index_2_link"/>
    <origin xyz="0.03 0 0" rpy="0 0 0"/>
    <axis xyz="0 1 0"/>
    <limit lower="0.0" upper="1.4888276999999999" effort="1.0" velocity="1.0"/>
    <mimic joint="index_1_joint" multiplier="1.1169" offset="0.0"/>
  </joint>
  <joint name="index_3_joint" type="fixed">
    <parent link="index_2_link"/>
    <child link="index_3_link"/>
    <origin xyz="0.022 0 0" rpy="0 0 0"/>
  </joint>
  <joint name="thumb_1_joint" type="revolute">
    <parent link="base_link"/>
    <child link="thumb_1_link"/>
    <origin xyz="-0.03 -0.04 0.015" rpy="0 0 0.7853981633974483"/>
    <axis xyz="0 0 1"/>
    <limit lower="0.0" upper="1.246" effort="1.0" velocity="1.0"/>
  </joint>
  <joint name="thumb_2_joint" type="revolute">
    <parent link="thumb_1_link"/>
    <child link="thumb_2_link"/>
    <origin xyz="0.025 0 0" rpy="0 0 0"/>
    <axis xyz="0 1 0"/>
    <limit lower="0.0" upper="0.48" effort="1.0" velocity="1.0"/>
  </joint>
  <joint name="thumb_3_joint" type="revolute">
    <parent link="thumb_2_link"/>
    <child link="thumb_3_link"/>
    <origin xyz="0.02 0 0" rpy="0 0 0"/>
    <axis xyz="0 1 0"/>
    <limit lower="0.0" upper="0.536112" effort="1.0" velocity="1.0"/>
    <mimic joint="thumb_2_joint" multiplier="1.1169" offset="0.0"/>
  </joint>
  <joint name="thumb_4_joint" type="fixed">
    <parent link="thumb_3_link"/>
    <child link="thumb_4_link"/>
    <origin xyz="0.015 0 0" rpy="0 0 0"/>
  </joint>
</robot>
