<?xml version="1.0" encoding="utf-8"?>
<!-- This URDF was automatically created by SolidWorks to URDF Exporter! Originally created by Stephen Brawner (brawner@gmail.com) 
     Commit Version: 1.6.0-4-g7f85cfe  Build Version: 1.6.7995.38578
     For more information, please see http://wiki.ros.org/sw_urdf_exporter -->
<robot xmlns:xacro="http://www.ros.org/wiki/xacro" name="RH56E2_L_2025_9_10">
  <!-- Dummy link to avoid KDL warning about root link inertia -->
  <link name="base_footprint"/>
  <joint name="base_footprint_to_base" type="fixed">
    <parent link="base_footprint"/>
    <child link="base_link"/>
    <origin xyz="0 0 0" rpy="0 0 0"/>
  </joint>
  <link
    name="base_link">
    <inertial>
      <origin
        xyz="0.000585306500185456 -4.36854347835025E-08 -0.018822662550448"
        rpy="0 0 0" />
      <mass
        value="0.090" />
      <inertia
        ixx="2.78685380929126E-05"
        ixy="-4.78139504897991E-11"
        ixz="-3.96465915290869E-08"
        iyy="2.67805393378652E-05"
        iyz="-1.05835026288552E-11"
        izz="3.64886767005748E-05" />
    </inertial>
    <visual>
      <origin
        xyz="0 0 0"
        rpy="0 0 0" />
      <geometry>
        <mesh
          filename="package://inspire_hand_description/meshes/left/base_link.STL" />
      </geometry>
      <material
        name="">
        <color
          rgba="1 1 1 1" />
      </material>
    </visual>
    <collision>
      <origin
        xyz="0 0 0"
        rpy="0 0 0" />
      <geometry>
        <mesh
          filename="package://inspire_hand_description/meshes/left/base_link.STL" />
      </geometry>
    </collision>
  </link>
  <link
    name="left_thumb_1">
    <inertial>
      <origin
        xyz="0.00067 0.004940000000000001 -0.00671"
        rpy="0 0 0" />
      <mass
        value="0.01537" />
      <inertia
        ixx="9.7931e-07"
        ixy="6.197e-08"
        ixz="-4.9e-09"
        iyy="6.735399999999999e-07"
        iyz="3.6289999999999996e-08"
        izz="8.6359e-07" />
    </inertial>
    <visual>
      <origin
        xyz="0 0 0"
        rpy="0 0 0" />
      <geometry>
        <mesh
          filename="package://inspire_hand_description/meshes/left/left_thumb_1.STL" />
      </geometry>
      <material
        name="">
        <color
          rgba="1 1 1 1" />
      </material>
    </visual>
    <collision>
      <origin
        xyz="0 0 0"
        rpy="0 0 0" />
      <geometry>
        <mesh
          filename="package://inspire_hand_description/meshes/left/left_thumb_1.STL" />
      </geometry>
    </collision>
  </link>
  <joint
    name="left_thumb_1_joint"
    type="revolute">
    <origin
      xyz="0.02101 0.0269 -0.0826"
      rpy="3.1416 0 0" />
    <parent
      link="base_link" />
    <child
      link="left_thumb_1" />
    <axis
      xyz="0 0 1" />
    <limit
      lower="0"
      upper="1.658"
      effort="1"
      velocity="2" />
  </joint>
  <link
    name="left_thumb_2">
    <inertial>
      <origin
        xyz="-0.03301 0.013460000000000001 0.00542"
        rpy="0 0 0" />
      <mass
        value="0.11034000000000001" />
      <inertia
        ixx="1.996898e-05"
        ixy="-1.123516e-05"
        ixz="-3.96656e-06"
        iyy="3.366305e-05"
        iyz="-1.22531e-06"
        izz="4.2347589999999993e-05" />
    </inertial>
    <visual>
      <origin
        xyz="0 0 0"
        rpy="0 0 0" />
      <geometry>
        <mesh
          filename="package://inspire_hand_description/meshes/left/left_thumb_2.STL" />
      </geometry>
      <material
        name="">
        <color
          rgba="0.25 0.25 0.25 1" />
      </material>
    </visual>
    <collision>
      <origin
        xyz="0 0 0"
        rpy="0 0 0" />
      <geometry>
        <mesh
          filename="package://inspire_hand_description/meshes/left/left_thumb_2.STL" />
      </geometry>
    </collision>
  </link>
  <joint
    name="left_thumb_2_joint"
    type="revolute">
    <origin
      xyz="0.013438 -0.012862 -0.0076"
      rpy="1.5708 0 -1.5708" />
    <parent
      link="left_thumb_1" />
    <child
      link="left_thumb_2" />
    <axis
      xyz="0.17365 0 0.98481" />
    <limit
      lower="0"
      upper="0.62"
      effort="1"
      velocity="2" />
  </joint>
  <link
    name="left_thumb_3">
    <inertial>
      <origin
        xyz="-0.01108 0.00155 0.011529999999999999"
        rpy="0 0 0" />
      <mass
        value="0.01779" />
      <inertia
        ixx="3.09353e-06"
        ixy="-3.9120999999999997e-07"
        ixz="1.2929999999999999e-08"
        iyy="2.57591e-06"
        iyz="7.61e-09"
        izz="3.32754e-06" />
    </inertial>
    <visual>
      <origin
        xyz="0 0 0"
        rpy="0 0 0" />
      <geometry>
        <mesh
          filename="package://inspire_hand_description/meshes/left/left_thumb_3.STL" />
      </geometry>
      <material
        name="">
        <color
          rgba="0.25 0.25 0.25 1" />
      </material>
    </visual>
    <collision>
      <origin
        xyz="0 0 0"
        rpy="0 0 0" />
      <geometry>
        <mesh
          filename="package://inspire_hand_description/meshes/left/left_thumb_3.STL" />
      </geometry>
    </collision>
  </link>
  <joint
    name="left_thumb_3_joint"
    type="revolute">
    <origin
      xyz="0.052954 0.032799 -0.0093372"
      rpy="0 0 0" />
    <parent
      link="left_thumb_2" />
    <child
      link="left_thumb_3" />
    <axis
      xyz="0.17365 0 0.98481" />
    <limit
      lower="0"
      upper="0.5410520681182421"
      effort="1"
      velocity="2" />
    <mimic
        joint="left_thumb_2_joint"
        multiplier="0.8392"
        offset="0" /> 
  </joint>
  <link
    name="left_thumb_force_sensor_2">
    <inertial>
      <origin
        xyz="-6.77023624058581E-05 0.00023698475781915 -0.000558267314746952"
        rpy="0 0 0" />
      <mass
        value="0.000119024235960817" />
      <inertia
        ixx="1.0224514684709E-09"
        ixy="-6.7224050154412E-13"
        ixz="-1.14240885059404E-12"
        iyy="9.97038953350155E-10"
        iyz="-8.16379211588012E-12"
        izz="1.9906514552054E-09" />
    </inertial>
    <visual>
      <origin
        xyz="0 0 0"
        rpy="0 0 0" />
      <geometry>
        <mesh
          filename="package://inspire_hand_description/meshes/left/left_thumb_force_sensor_2.STL" />
      </geometry>
      <material
        name="">
        <color
          rgba="0.25 0.25 0.25 1" />
      </material>
    </visual>
    <collision>
      <origin
        xyz="0 0 0"
        rpy="0 0 0" />
      <geometry>
        <mesh
          filename="package://inspire_hand_description/meshes/left/left_thumb_force_sensor_2.STL" />
      </geometry>
    </collision>
  </link>
  <joint
    name="left_thumb_force_sensor_2_joint"
    type="fixed">
    <origin
      xyz="0.0080283 0.016443 0.00982"
      rpy="0.96258 1.4071 3.0993" />
    <parent
      link="left_thumb_3" />
    <child
      link="left_thumb_force_sensor_2" />
    <axis
      xyz="0 0 0" />
  </joint>
  <link
    name="left_thumb_4">
    <inertial>
      <origin
        xyz="-0.01264 0.007730000000000001 0.0105"
        rpy="0 0 0" />
      <mass
        value="0.00766" />
      <inertia
        ixx="1.15326e-06"
        ixy="-1.6573e-07"
        ixz="-4.0000000000000004e-11"
        iyy="5.7535e-07"
        iyz="7e-11"
        izz="1.15929e-06" />
    </inertial>
    <visual>
      <origin
        xyz="0 0 0"
        rpy="0 0 0" />
      <geometry>
        <mesh
          filename="package://inspire_hand_description/meshes/left/left_thumb_4.STL" />
      </geometry>
      <material
        name="">
        <color
          rgba="0.25 0.25 0.25 1" />
      </material>
    </visual>
    <collision>
      <origin
        xyz="0 0 0"
        rpy="0 0 0" />
      <geometry>
        <mesh
          filename="package://inspire_hand_description/meshes/left/left_thumb_4.STL" />
      </geometry>
    </collision>
  </link>
  <joint
    name="left_thumb_4_joint"
    type="revolute">
    <origin
      xyz="0.01865 0.013373 -0.0022731"
      rpy="0 0 0" />
    <parent
      link="left_thumb_3" />
    <child
      link="left_thumb_4" />
    <axis
      xyz="0.17365 0 0.98481" />
    <limit
      lower="0"
      upper="0.45553093477052004"
      effort="1"
      velocity="2" />
    <mimic
        joint="left_thumb_3_joint"
        multiplier="0.891"
        offset="0" />  
  </joint>
  <link
    name="left_thumb_force_sensor_3">
    <inertial>
      <origin
        xyz="2.75155276924233E-07 0.000696644789683842 -0.000425123283601309"
        rpy="0 0 0" />
      <mass
        value="0.000169894176021865" />
      <inertia
        ixx="3.91695563569899E-09"
        ixy="-3.84881369197044E-15"
        ixz="2.56832047427422E-13"
        iyy="1.41883437204732E-09"
        iyz="-1.72956740679056E-10"
        izz="5.29524834856028E-09" />
    </inertial>
    <visual>
      <origin
        xyz="0 0 0"
        rpy="0 0 0" />
      <geometry>
        <mesh
          filename="package://inspire_hand_description/meshes/left/left_thumb_force_sensor_3.STL" />
      </geometry>
      <material
        name="">
        <color
          rgba="0.25 0.25 0.25 1" />
      </material>
    </visual>
    <collision>
      <origin
        xyz="0 0 0"
        rpy="0 0 0" />
      <geometry>
        <mesh
          filename="package://inspire_hand_description/meshes/left/left_thumb_force_sensor_3.STL" />
      </geometry>
    </collision>
  </link>
  <joint
    name="left_thumb_force_sensor_3_joint"
    type="fixed">
    <origin
      xyz="0.0076349 0.020486 0.0088094"
      rpy="0.64092 1.3963 -3.1415" />
    <parent
      link="left_thumb_4" />
    <child
      link="left_thumb_force_sensor_3" />
    <axis
      xyz="0 0 0" />
  </joint>
  <link
    name="left_thumb_force_sensor_4">
    <inertial>
      <origin
        xyz="1.53421438291515E-06 -0.000421608116505295 -0.000751976730520715"
        rpy="0 0 0" />
      <mass
        value="1.66991074236564E-05" />
      <inertia
        ixx="2.2577332779412E-11"
        ixy="2.52363008433222E-15"
        ixz="-5.30005584942463E-15"
        iyy="2.30774417460483E-11"
        iyz="1.74406833632406E-13"
        izz="4.31637280809456E-11" />
    </inertial>
    <visual>
      <origin
        xyz="0 0 0"
        rpy="0 0 0" />
      <geometry>
        <mesh
          filename="package://inspire_hand_description/meshes/left/left_thumb_force_sensor_4.STL" />
      </geometry>
      <material
        name="">
        <color
          rgba="0.25 0.25 0.25 1" />
      </material>
    </visual>
    <collision>
      <origin
        xyz="0 0 0"
        rpy="0 0 0" />
      <geometry>
        <mesh
          filename="package://inspire_hand_description/meshes/left/left_thumb_force_sensor_4.STL" />
      </geometry>
    </collision>
  </link>
  <joint
    name="left_thumb_force_sensor_4_joint"
    type="fixed">
    <origin
      xyz="0.018831 0.027914 0.0068352"
      rpy="1.7521 1.3962 -3.1401" />
    <parent
      link="left_thumb_4" />
    <child
      link="left_thumb_force_sensor_4" />
    <axis
      xyz="0 0 0" />
  </joint>
  <link
    name="left_thumb_force_sensor_1">
    <inertial>
      <origin
        xyz="-0.000315253413178729 8.00831279870462E-05 -0.000511444693418101"
        rpy="0 0 0" />
      <mass
        value="0.000234351522411044" />
      <inertia
        ixx="6.82585459105814E-09"
        ixy="1.33330535751836E-11"
        ixz="-9.2406741263255E-12"
        iyy="2.91720696731406E-09"
        iyz="-1.79692153239885E-10"
        izz="9.68920415325705E-09" />
    </inertial>
    <visual>
      <origin
        xyz="0 0 0"
        rpy="0 0 0" />
      <geometry>
        <mesh
          filename="package://inspire_hand_description/meshes/left/left_thumb_force_sensor_1.STL" />
      </geometry>
      <material
        name="">
        <color
          rgba="0.25 0.25 0.25 1" />
      </material>
    </visual>
    <collision>
      <origin
        xyz="0 0 0"
        rpy="0 0 0" />
      <geometry>
        <mesh
          filename="package://inspire_hand_description/meshes/left/left_thumb_force_sensor_1.STL" />
      </geometry>
    </collision>
  </link>
  <joint
    name="left_thumb_force_sensor_1_joint"
    type="fixed">
    <origin
      xyz="0.023412 0.033251 0.0070079"
      rpy="1.1285 1.3976 3.1383" />
    <parent
      link="left_thumb_2" />
    <child
      link="left_thumb_force_sensor_1" />
    <axis
      xyz="0 0 0" />
  </joint>
  <link
    name="left_index_1">
    <inertial>
      <origin
        xyz="0.00132 0.01078 0.00805"
        rpy="0 0 0" />
      <mass
        value="0.018690000000000002" />
      <inertia
        ixx="3.59962e-06"
        ixy="4.1645999999999996e-07"
        ixz="-1.6599999999999999e-09"
        iyy="1.20603e-06"
        iyz="6.3e-10"
        izz="3.79687e-06" />
    </inertial>
    <visual>
      <origin
        xyz="0 0 0"
        rpy="0 0 0" />
      <geometry>
        <mesh
          filename="package://inspire_hand_description/meshes/left/left_index_1.STL" />
      </geometry>
      <material
        name="">
        <color
          rgba="0.25 0.25 0.25 1" />
      </material>
    </visual>
    <collision>
      <origin
        xyz="0 0 0"
        rpy="0 0 0" />
      <geometry>
        <mesh
          filename="package://inspire_hand_description/meshes/left/left_index_1.STL" />
      </geometry>
    </collision>
  </link>
  <joint
    name="left_index_1_joint"
    type="revolute">
    <origin
      xyz="0.00056467 0.038679 -0.1564"
      rpy="-1.5359 0 0" />
    <parent
      link="base_link" />
    <child
      link="left_index_1" />
    <axis
      xyz="0 0 -1" />
    <limit
      lower="0"
      upper="1.4381"
      effort="1"
      velocity="2" />
  </joint>
  <link
    name="left_index_2">
    <inertial>
      <origin
        xyz="-0.00016 0.0177 0.008"
        rpy="0 0 0" />
      <mass
        value="0.01102" />
      <inertia
        ixx="2.32185e-06"
        ixy="5.6428e-07"
        ixz="9e-11"
        iyy="4.134e-07"
        iyz="-3.9e-10"
        izz="2.4238400000000002e-06" />
    </inertial>
    <visual>
      <origin
        xyz="0 0 0"
        rpy="0 0 0" />
      <geometry>
        <mesh
          filename="package://inspire_hand_description/meshes/left/left_index_2.STL" />
      </geometry>
      <material
        name="">
        <color
          rgba="0.25 0.25 0.25 1" />
      </material>
    </visual>
    <collision>
      <origin
        xyz="0 0 0"
        rpy="0 0 0" />
      <geometry>
        <mesh
          filename="package://inspire_hand_description/meshes/left/left_index_2.STL" />
      </geometry>
    </collision>
  </link>
  <joint
    name="left_index_2_joint"
    type="revolute">
    <origin
      xyz="0.0034259 0.032596 -0.00055"
      rpy="0 0 0" />
    <parent
      link="left_index_1" />
    <child
      link="left_index_2" />
    <axis
      xyz="0 0 -1" />
    <limit
      lower="0"
      upper="1.476374"
      effort="1"
      velocity="2" />
    <mimic
        joint="left_index_1_joint"
        multiplier="1.0843"
        offset="0" />  
  </joint>
  <link
    name="left_index_force_sensor_2">
    <inertial>
      <origin
        xyz="-0.000722888601375635 0.000206469730474002 3.92383751648961E-06"
        rpy="0 0 0" />
      <mass
        value="0.000255748193489171" />
      <inertia
        ixx="7.12568463704182E-09"
        ixy="-3.0516440505427E-11"
        ixz="-1.50421802884703E-12"
        iyy="2.43957953886851E-09"
        iyz="-8.64189585164301E-11"
        izz="4.79877681662902E-09" />
    </inertial>
    <visual>
      <origin
        xyz="0 0 0"
        rpy="0 0 0" />
      <geometry>
        <mesh
          filename="package://inspire_hand_description/meshes/left/left_index_force_sensor_2.STL" />
      </geometry>
      <material
        name="">
        <color
          rgba="0.25 0.25 0.25 1" />
      </material>
    </visual>
    <collision>
      <origin
        xyz="0 0 0"
        rpy="0 0 0" />
      <geometry>
        <mesh
          filename="package://inspire_hand_description/meshes/left/left_index_force_sensor_2.STL" />
      </geometry>
    </collision>
  </link>
  <joint
    name="left_index_force_sensor_2_joint"
    type="fixed">
    <origin
      xyz="0.0081655 0.037446 -0.0060795"
      rpy="-0.037141 0 -0.34877" />
    <parent
      link="left_index_2" />
    <child
      link="left_index_force_sensor_2" />
    <axis
      xyz="0 0 0" />
  </joint>
  <link
    name="left_index_force_sensor_3">
    <inertial>
      <origin
        xyz="2.48711721375083E-05 -0.000345284190379214 -0.00133798868635948"
        rpy="0 0 0" />
      <mass
        value="6.79653902597574E-05" />
      <inertia
        ixx="1.31976080328049E-10"
        ixy="-5.65097777117389E-12"
        ixz="-7.80108678689416E-13"
        iyy="2.53434465829639E-10"
        iyz="9.12174680571318E-12"
        izz="2.80536891506937E-10" />
    </inertial>
    <visual>
      <origin
        xyz="0 0 0"
        rpy="0 0 0" />
      <geometry>
        <mesh
          filename="package://inspire_hand_description/meshes/left/left_index_force_sensor_3.STL" />
      </geometry>
      <material
        name="">
        <color
          rgba="0.25 0.25 0.25 1" />
      </material>
    </visual>
    <collision>
      <origin
        xyz="0 0 0"
        rpy="0 0 0" />
      <geometry>
        <mesh
          filename="package://inspire_hand_description/meshes/left/left_index_force_sensor_3.STL" />
      </geometry>
    </collision>
  </link>
  <joint
    name="left_index_force_sensor_3_joint"
    type="fixed">
    <origin
      xyz="0.0086237 0.052572 -0.0060954"
      rpy="-1.5708 1.5252 -0.87237" />
    <parent
      link="left_index_2" />
    <child
      link="left_index_force_sensor_3" />
    <axis
      xyz="0 0 0" />
  </joint>
  <link
    name="left_index_force_sensor_1">
    <inertial>
      <origin
        xyz="-4.3998E-06 0.00011649 -0.00056743"
        rpy="0 0 0" />
      <mass
        value="0.00020279" />
      <inertia
        ixx="3.3806E-09"
        ixy="5.0688E-11"
        ixz="2.189E-13"
        iyy="1.9643E-09"
        iyz="-5.5263E-12"
        izz="5.2813E-09" />
    </inertial>
    <visual>
      <origin
        xyz="0 0 0"
        rpy="0 0 0" />
      <geometry>
        <mesh
          filename="package://inspire_hand_description/meshes/left/left_index_force_sensor_1.STL" />
      </geometry>
      <material
        name="">
        <color
          rgba="0.25 0.25 0.25 1" />
      </material>
    </visual>
    <collision>
      <origin
        xyz="0 0 0"
        rpy="0 0 0" />
      <geometry>
        <mesh
          filename="package://inspire_hand_description/meshes/left/left_index_force_sensor_1.STL" />
      </geometry>
    </collision>
  </link>
  <joint
    name="left_index_force_sensor_1_joint"
    type="fixed">
    <origin
      xyz="0.012046 0.019649 -0.006651"
      rpy="-1.5708 1.5351 -1.3587" />
    <parent
      link="left_index_1" />
    <child
      link="left_index_force_sensor_1" />
    <axis
      xyz="0 0 0" />
  </joint>
  <link
    name="left_middle_1">
    <inertial>
      <origin
        xyz="0.0013700000000000001 0.011009999999999999 0.008060000000000001"
        rpy="0 0 0" />
      <mass
        value="0.01866" />
      <inertia
        ixx="3.59341e-06"
        ixy="4.0058999999999996e-07"
        ixz="-1.64e-09"
        iyy="1.20028e-06"
        iyz="1.21e-09"
        izz="3.7852399999999996e-06" />
    </inertial>
    <visual>
      <origin
        xyz="0 0 0"
        rpy="0 0 0" />
      <geometry>
        <mesh
          filename="package://inspire_hand_description/meshes/left/left_middle_1.STL" />
      </geometry>
      <material
        name="">
        <color
          rgba="0.25 0.25 0.25 1" />
      </material>
    </visual>
    <collision>
      <origin
        xyz="0 0 0"
        rpy="0 0 0" />
      <geometry>
        <mesh
          filename="package://inspire_hand_description/meshes/left/left_middle_1.STL" />
      </geometry>
    </collision>
  </link>
  <joint
    name="left_middle_1_joint"
    type="revolute">
    <origin
      xyz="0.00056467 0.0171 -0.157"
      rpy="-1.5708 0 0" />
    <parent
      link="base_link" />
    <child
      link="left_middle_1" />
    <axis
      xyz="0 0 -1" />
    <limit
      lower="0"
      upper="1.4381"
      effort="1"
      velocity="2" />
  </joint>
  <link
    name="left_middle_2">
    <inertial>
      <origin
        xyz="0.0019 0.02314 0.00802"
        rpy="0 0 0" />
      <mass
        value="0.01767" />
      <inertia
        ixx="4.63728e-06"
        ixy="1.35163e-06"
        ixz="2.92e-09"
        iyy="9.821e-07"
        iyz="-1.151e-08"
        izz="5.00365e-06" />
    </inertial>
    <visual>
      <origin
        xyz="0 0 0"
        rpy="0 0 0" />
      <geometry>
        <mesh
          filename="package://inspire_hand_description/meshes/left/left_middle_2.STL" />
      </geometry>
      <material
        name="">
        <color
          rgba="0.25 0.25 0.25 1" />
      </material>
    </visual>
    <collision>
      <origin
        xyz="0 0 0"
        rpy="0 0 0" />
      <geometry>
        <mesh
          filename="package://inspire_hand_description/meshes/left/left_middle_2.STL" />
      </geometry>
    </collision>
  </link>
  <joint
    name="left_middle_2_joint"
    type="revolute">
    <origin
      xyz="0.0034259 0.032596 -0.00055"
      rpy="0 0 0" />
    <parent
      link="left_middle_1" />
    <child
      link="left_middle_2" />
    <axis
      xyz="0 0 -1" />
    <limit
      lower="0"
      upper="1.476374"
      effort="1"
      velocity="2" />
    <mimic
        joint="left_middle_1_joint"
        multiplier="1.0843"
        offset="0" />
  </joint>
  <link
    name="left_middle_force_sensor_2">
    <inertial>
      <origin
        xyz="6.77351601419129E-07 2.94313229363685E-05 -0.00072242577649223"
        rpy="0 0 0" />
      <mass
        value="0.000262573593923136" />
      <inertia
        ixx="5.0414876593695E-09"
        ixy="1.87053180725797E-13"
        ixz="-1.92198399992304E-14"
        iyy="2.56777987860698E-09"
        iyz="3.4715059658037E-12"
        izz="7.49457837348385E-09" />
    </inertial>
    <visual>
      <origin
        xyz="0 0 0"
        rpy="0 0 0" />
      <geometry>
        <mesh
          filename="package://inspire_hand_description/meshes/left/left_middle_force_sensor_2.STL" />
      </geometry>
      <material
        name="">
        <color
          rgba="0.25 0.25 0.25 1" />
      </material>
    </visual>
    <collision>
      <origin
        xyz="0 0 0"
        rpy="0 0 0" />
      <geometry>
        <mesh
          filename="package://inspire_hand_description/meshes/left/left_middle_force_sensor_2.STL" />
      </geometry>
    </collision>
  </link>
  <joint
    name="left_middle_force_sensor_2_joint"
    type="fixed">
    <origin
      xyz="0.009086 0.040962 -0.0061003"
      rpy="-1.0917 1.5708 -1.4646" />
    <parent
      link="left_middle_2" />
    <child
      link="left_middle_force_sensor_2" />
    <axis
      xyz="0 0 0" />
  </joint>
  <link
    name="left_middle_force_sensor_3">
    <inertial>
      <origin
        xyz="-8.06940798625533E-08 -0.00036544469914071 -0.00127684015275201"
        rpy="0 0 0" />
      <mass
        value="6.64914272946078E-05" />
      <inertia
        ixx="1.27227716200643E-10"
        ixy="-8.96643675660692E-15"
        ixz="-8.77104798534102E-15"
        iyy="2.43691020872163E-10"
        iyz="7.612765414699E-12"
        izz="2.75875028961974E-10" />
    </inertial>
    <visual>
      <origin
        xyz="0 0 0"
        rpy="0 0 0" />
      <geometry>
        <mesh
          filename="package://inspire_hand_description/meshes/left/left_middle_force_sensor_3.STL" />
      </geometry>
      <material
        name="">
        <color
          rgba="0.25 0.25 0.25 1" />
      </material>
    </visual>
    <collision>
      <origin
        xyz="0 0 0"
        rpy="0 0 0" />
      <geometry>
        <mesh
          filename="package://inspire_hand_description/meshes/left/left_middle_force_sensor_3.STL" />
      </geometry>
    </collision>
  </link>
  <joint
    name="left_middle_force_sensor_3_joint"
    type="fixed">
    <origin
      xyz="0.0098294 0.056051 -0.0061006"
      rpy="-2.1401 1.5708 -1.4657" />
    <parent
      link="left_middle_2" />
    <child
      link="left_middle_force_sensor_3" />
    <axis
      xyz="0 0 0" />
  </joint>
  <link
    name="left_middle_force_sensor_1">
    <inertial>
      <origin
        xyz="-2.38805233365724E-07 0.000116575254234724 -0.000567426156928438"
        rpy="0 0 0" />
      <mass
        value="0.000202794522112893" />
      <inertia
        ixx="3.38243621902089E-09"
        ixy="2.84614711307975E-14"
        ixz="2.15581663022967E-14"
        iyy="1.96244127906421E-09"
        iyz="-5.53035968075616E-12"
        izz="5.28129636598907E-09" />
    </inertial>
    <visual>
      <origin
        xyz="0 0 0"
        rpy="0 0 0" />
      <geometry>
        <mesh
          filename="package://inspire_hand_description/meshes/left/left_middle_force_sensor_1.STL" />
      </geometry>
      <material
        name="">
        <color
          rgba="0.25 0.25 0.25 1" />
      </material>
    </visual>
    <collision>
      <origin
        xyz="0 0 0"
        rpy="0 0 0" />
      <geometry>
        <mesh
          filename="package://inspire_hand_description/meshes/left/left_middle_force_sensor_1.STL" />
      </geometry>
    </collision>
  </link>
  <joint
    name="left_middle_force_sensor_1_joint"
    type="fixed">
    <origin
      xyz="0.012046 0.019649 -0.006651"
      rpy="-1.9353 1.5708 -1.7232" />
    <parent
      link="left_middle_1" />
    <child
      link="left_middle_force_sensor_1" />
    <axis
      xyz="0 0 0" />
  </joint>
  <link
    name="left_ring_1">
    <inertial>
      <origin
        xyz="0.0011899999999999999 0.01036 0.00861"
        rpy="0 0 0" />
      <mass
        value="0.018690000000000002" />
      <inertia
        ixx="3.60961e-06"
        ixy="3.8725e-07"
        ixz="-2.1949999999999998e-08"
        iyy="1.20307e-06"
        iyz="1.3659e-07"
        izz="3.78952e-06" />
    </inertial>
    <visual>
      <origin
        xyz="0 0 0"
        rpy="0 0 0" />
      <geometry>
        <mesh
          filename="package://inspire_hand_description/meshes/left/left_ring_1.STL" />
      </geometry>
      <material
        name="">
        <color
          rgba="0.25 0.25 0.25 1" />
      </material>
    </visual>
    <collision>
      <origin
        xyz="0 0 0"
        rpy="0 0 0" />
      <geometry>
        <mesh
          filename="package://inspire_hand_description/meshes/left/left_ring_1.STL" />
      </geometry>
    </collision>
  </link>
  <joint
    name="left_ring_1_joint"
    type="revolute">
    <origin
      xyz="0.00056467 -0.0045302 -0.15683"
      rpy="-1.6232 0 0" />
    <parent
      link="base_link" />
    <child
      link="left_ring_1" />
    <axis
      xyz="0 0 -1" />
    <limit
      lower="0"
      upper="1.4381"
      effort="1"
      velocity="2" />
  </joint>
  <link
    name="left_ring_2">
    <inertial>
      <origin
        xyz="-0.00057 0.01725 0.00891"
        rpy="0 0 0" />
      <mass
        value="0.01102" />
      <inertia
        ixx="2.3471100000000002e-06"
        ixy="5.196000000000001e-07"
        ixz="-2.702e-08"
        iyy="3.9493e-07"
        iyz="1.0668000000000001e-07"
        izz="2.41823e-06" />
    </inertial>
    <visual>
      <origin
        xyz="0 0 0"
        rpy="0 0 0" />
      <geometry>
        <mesh
          filename="package://inspire_hand_description/meshes/left/left_ring_2.STL" />
      </geometry>
      <material
        name="">
        <color
          rgba="0.25 0.25 0.25 1" />
      </material>
    </visual>
    <collision>
      <origin
        xyz="0 0 0"
        rpy="0 0 0" />
      <geometry>
        <mesh
          filename="package://inspire_hand_description/meshes/left/left_ring_2.STL" />
      </geometry>
    </collision>
  </link>
  <joint
    name="left_ring_2_joint"
    type="revolute">
    <origin
      xyz="0.0034259 0.032596 -0.00055"
      rpy="0 0 0" />
    <parent
      link="left_ring_1" />
    <child
      link="left_ring_2" />
    <axis
      xyz="0 0 -1" />
    <limit
      lower="0"
      upper="1.476374"
      effort="1"
      velocity="2" />
    <mimic
        joint="left_ring_1_joint"
        multiplier="1.0843"
        offset="0" />
  </joint>
  <link
    name="left_ring_force_sensor_2">
    <inertial>
      <origin
        xyz="1.52347834204147E-05 0.000205944196068869 -0.000722888366917224"
        rpy="0 0 0" />
      <mass
        value="0.000255748190883527" />
      <inertia
        ixx="4.79445247031254E-09"
        ixy="-1.32856442478724E-10"
        ixz="-1.33138092624363E-12"
        iyy="2.44390356832089E-09"
        iyz="-3.0524509743324E-11"
        izz="7.1256841969102E-09" />
    </inertial>
    <visual>
      <origin
        xyz="0 0 0"
        rpy="0 0 0" />
      <geometry>
        <mesh
          filename="package://inspire_hand_description/meshes/left/left_ring_force_sensor_2.STL" />
      </geometry>
      <material
        name="">
        <color
          rgba="0.25 0.25 0.25 1" />
      </material>
    </visual>
    <collision>
      <origin
        xyz="0 0 0"
        rpy="0 0 0" />
      <geometry>
        <mesh
          filename="package://inspire_hand_description/meshes/left/left_ring_force_sensor_2.STL" />
      </geometry>
    </collision>
  </link>
  <joint
    name="left_ring_force_sensor_2_joint"
    type="fixed">
    <origin
      xyz="0.0081655 0.037446 -0.0060795"
      rpy="1.5708 1.5151 1.222" />
    <parent
      link="left_ring_2" />
    <child
      link="left_ring_force_sensor_2" />
    <axis
      xyz="0 0 0" />
  </joint>
  <link
    name="left_ring_force_sensor_3">
    <inertial>
      <origin
        xyz="-1.45503841600947E-05 -0.00034586662981545 -0.00133798468205445"
        rpy="0 0 0" />
      <mass
        value="6.79657634628817E-05" />
      <inertia
        ixx="1.32269553838889E-10"
        ixy="8.21009692820913E-12"
        ixz="2.62881491754241E-13"
        iyy="2.53144228524505E-10"
        iyz="9.1509693922259E-12"
        izz="2.80539793431039E-10" />
    </inertial>
    <visual>
      <origin
        xyz="0 0 0"
        rpy="0 0 0" />
      <geometry>
        <mesh
          filename="package://inspire_hand_description/meshes/left/left_ring_force_sensor_3.STL" />
      </geometry>
      <material
        name="">
        <color
          rgba="0.25 0.25 0.25 1" />
      </material>
    </visual>
    <collision>
      <origin
        xyz="0 0 0"
        rpy="0 0 0" />
      <geometry>
        <mesh
          filename="package://inspire_hand_description/meshes/left/left_ring_force_sensor_3.STL" />
      </geometry>
    </collision>
  </link>
  <joint
    name="left_ring_force_sensor_3_joint"
    type="fixed">
    <origin
      xyz="0.0086237 0.052572 -0.0060954"
      rpy="1.5708 1.5025 2.2692" />
    <parent
      link="left_ring_2" />
    <child
      link="left_ring_force_sensor_3" />
    <axis
      xyz="0 0 0" />
  </joint>
  <link
    name="left_ring_force_sensor_1">
    <inertial>
      <origin
        xyz="6.00203522233E-06 0.000116421389729365 -0.000567426346437278"
        rpy="0 0 0" />
      <mass
        value="0.000202794434376476" />
      <inertia
        ixx="3.37837011170987E-09"
        ixy="-7.5878752969108E-11"
        ixz="-2.74580423233197E-13"
        iyy="1.9665061826483E-09"
        iyz="-5.52393135574737E-12"
        izz="5.28129521919666E-09" />
    </inertial>
    <visual>
      <origin
        xyz="0 0 0"
        rpy="0 0 0" />
      <geometry>
        <mesh
          filename="package://inspire_hand_description/meshes/left/left_ring_force_sensor_1.STL" />
      </geometry>
      <material
        name="">
        <color
          rgba="0.25 0.25 0.25 1" />
      </material>
    </visual>
    <collision>
      <origin
        xyz="0 0 0"
        rpy="0 0 0" />
      <geometry>
        <mesh
          filename="package://inspire_hand_description/meshes/left/left_ring_force_sensor_1.STL" />
      </geometry>
    </collision>
  </link>
  <joint
    name="left_ring_force_sensor_1_joint"
    type="fixed">
    <origin
      xyz="0.012046 0.019649 -0.006651"
      rpy="1.5708 1.5172 1.7829" />
    <parent
      link="left_ring_1" />
    <child
      link="left_ring_force_sensor_1" />
    <axis
      xyz="0 0 0" />
  </joint>
  <link
    name="left_little_1">
    <inertial>
      <origin
        xyz="0.0008100000000000001 0.00991 0.00914"
        rpy="0 0 0" />
      <mass
        value="0.018690000000000002" />
      <inertia
        ixx="3.6346399999999997e-06"
        ixy="3.0236e-07"
        ixz="-3.3420000000000004e-08"
        iyy="1.19929e-06"
        iyz="2.7369e-07"
        izz="3.76746e-06" />
    </inertial>
    <visual>
      <origin
        xyz="0 0 0"
        rpy="0 0 0" />
      <geometry>
        <mesh
          filename="package://inspire_hand_description/meshes/left/left_little_1.STL" />
      </geometry>
      <material
        name="">
        <color
          rgba="0.25 0.25 0.25 1" />
      </material>
    </visual>
    <collision>
      <origin
        xyz="0 0 0"
        rpy="0 0 0" />
      <geometry>
        <mesh
          filename="package://inspire_hand_description/meshes/left/left_little_1.STL" />
      </geometry>
    </collision>
  </link>
  <joint
    name="left_little_1_joint"
    type="revolute">
    <origin
      xyz="0.00056467 -0.025916 -0.15365"
      rpy="-1.6755 0 0" />
    <parent
      link="base_link" />
    <child
      link="left_little_1" />
    <axis
      xyz="0 0 -1" />
    <limit
      lower="0"
      upper="1.4381"
      effort="1"
      velocity="2" />
  </joint>
  <link
    name="left_little_2">
    <inertial>
      <origin
        xyz="0.0008100000000000001 0.00991 0.00914"
        rpy="0 0 0" />
      <mass
        value="0.018690000000000002" />
      <inertia
        ixx="3.6346399999999997e-06"
        ixy="3.0236e-07"
        ixz="-3.3420000000000004e-08"
        iyy="1.19929e-06"
        iyz="2.7369e-07"
        izz="3.76746e-06" />
    </inertial>
    <visual>
      <origin
        xyz="0 0 0"
        rpy="0 0 0" />
      <geometry>
        <mesh
          filename="package://inspire_hand_description/meshes/left/left_little_2.STL" />
      </geometry>
      <material
        name="">
        <color
          rgba="0.25 0.25 0.25 1" />
      </material>
    </visual>
    <collision>
      <origin
        xyz="0 0 0"
        rpy="0 0 0" />
      <geometry>
        <mesh
          filename="package://inspire_hand_description/meshes/left/left_little_2.STL" />
      </geometry>
    </collision>
  </link>
  <joint
    name="left_little_2_joint"
    type="revolute">
    <origin
      xyz="0.0034259 0.032596 -0.00055"
      rpy="0 0 0" />
    <parent
      link="left_little_1" />
    <child
      link="left_little_2" />
    <axis
      xyz="0 0 -1" />
    <limit
      lower="0"
      upper="1.476374"
      effort="1"
      velocity="2" />
    <mimic
        joint="left_little_1_joint"
        multiplier="1.0843"
        offset="0" />  
  </joint>
  <link
    name="left_little_force_sensor_2">
    <inertial>
      <origin
        xyz="-1.80617030003938E-05 -0.000118388090762839 -0.000773722865995793"
        rpy="0 0 0" />
      <mass
        value="0.00028024674848609" />
      <inertia
        ixx="5.3604473912048E-09"
        ixy="-2.90383767216199E-10"
        ixz="4.21250471348326E-12"
        iyy="2.78880843363607E-09"
        iyz="3.60559684736873E-11"
        izz="8.00957473963412E-09" />
    </inertial>
    <visual>
      <origin
        xyz="0 0 0"
        rpy="0 0 0" />
      <geometry>
        <mesh
          filename="package://inspire_hand_description/meshes/left/left_little_force_sensor_2.STL" />
      </geometry>
      <material
        name="">
        <color
          rgba="0.25 0.25 0.25 1" />
      </material>
    </visual>
    <collision>
      <origin
        xyz="0 0 0"
        rpy="0 0 0" />
      <geometry>
        <mesh
          filename="package://inspire_hand_description/meshes/left/left_little_force_sensor_2.STL" />
      </geometry>
    </collision>
  </link>
  <joint
    name="left_little_force_sensor_2_joint"
    type="fixed">
    <origin
      xyz="0.0064514 0.027683 -0.0061172"
      rpy="1.5708 1.4597 1.2289" />
    <parent
      link="left_little_2" />
    <child
      link="left_little_force_sensor_2" />
    <axis
      xyz="0 0 0" />
  </joint>
  <link
    name="left_little_force_sensor_3">
    <inertial>
      <origin
        xyz="-6.37037928365447E-05 -0.000437210531355342 -0.00112816117408027"
        rpy="0 0 0" />
      <mass
        value="6.1053667014177E-05" />
      <inertia
        ixx="1.11591596284049E-10"
        ixy="1.48923286911394E-11"
        ixz="1.18294492348375E-12"
        iyy="2.17206534673202E-10"
        iyz="8.078835709315E-12"
        izz="2.52052305203803E-10" />
    </inertial>
    <visual>
      <origin
        xyz="0 0 0"
        rpy="0 0 0" />
      <geometry>
        <mesh
          filename="package://inspire_hand_description/meshes/left/left_little_force_sensor_3.STL" />
      </geometry>
      <material
        name="">
        <color
          rgba="0.25 0.25 0.25 1" />
      </material>
    </visual>
    <collision>
      <origin
        xyz="0 0 0"
        rpy="0 0 0" />
      <geometry>
        <mesh
          filename="package://inspire_hand_description/meshes/left/left_little_force_sensor_3.STL" />
      </geometry>
    </collision>
  </link>
  <joint
    name="left_little_force_sensor_3_joint"
    type="fixed">
    <origin
      xyz="0.0063973 0.042707 -0.0061154"
      rpy="1.5708 1.4336 2.2761" />
    <parent
      link="left_little_2" />
    <child
      link="left_little_force_sensor_3" />
    <axis
      xyz="0 0 0" />
  </joint>
  <link
    name="left_little_force_sensor_1">
    <inertial>
      <origin
        xyz="1.22242688667118E-05 0.000115932853490763 -0.000567426208360044"
        rpy="0 0 0" />
      <mass
        value="0.000202794502264302" />
      <inertia
        ixx="3.3662161038664E-09"
        ixy="-1.50896082438854E-10"
        ixz="-5.69773684986878E-13"
        iyy="1.97866156369565E-09"
        iyz="-5.50105749422691E-12"
        izz="5.28129655313475E-09" />
    </inertial>
    <visual>
      <origin
        xyz="0 0 0"
        rpy="0 0 0" />
      <geometry>
        <mesh
          filename="package://inspire_hand_description/meshes/left/left_little_force_sensor_1.STL" />
      </geometry>
      <material
        name="">
        <color
          rgba="0.25 0.25 0.25 1" />
      </material>
    </visual>
    <collision>
      <origin
        xyz="0 0 0"
        rpy="0 0 0" />
      <geometry>
        <mesh
          filename="package://inspire_hand_description/meshes/left/left_little_force_sensor_1.STL" />
      </geometry>
    </collision>
  </link>
  <joint
    name="left_little_force_sensor_1_joint"
    type="fixed">
    <origin
      xyz="0.012046 0.019649 -0.006651"
      rpy="1.5708 1.4637 1.7829" />
    <parent
      link="left_little_1" />
    <child
      link="left_little_force_sensor_1" />
    <axis
      xyz="0 0 0" />
  </joint>
  <link
    name="left_palm_1">
    <inertial>
      <origin
        xyz="-0.00625 0.0022299999999999998 0.0689"
        rpy="0 0 0" />
      <mass
        value="0.38382" />
      <inertia
        ixx="0.00054913744"
        ixy="4.42438e-06"
        ixz="2.9859009999999997e-05"
        iyy="0.00040036048"
        iyz="-9.570770000000001e-06"
        izz="0.00022521596" />
    </inertial>
    <visual>
      <origin
        xyz="0 0 0"
        rpy="0 0 0" />
      <geometry>
        <mesh
          filename="package://inspire_hand_description/meshes/left/left_palm_1.STL" />
      </geometry>
      <material
        name="">
        <color
          rgba="0.25 0.25 0.25 1" />
      </material>
    </visual>
    <collision>
      <origin
        xyz="0 0 0"
        rpy="0 0 0" />
      <geometry>
        <mesh
          filename="package://inspire_hand_description/meshes/left/left_palm_1.STL" />
      </geometry>
    </collision>
  </link>
  <joint
    name="left_palm_1_joint"
    type="fixed">
    <origin
      xyz="0 0 -0.031"
      rpy="-3.1416 0 0" />
    <parent
      link="base_link" />
    <child
      link="left_palm_1" />
    <axis
      xyz="0 0 0" />
  </joint>
  <link
    name="left_palm_2">
    <inertial>
      <origin
        xyz="-0.0282279108648417 -0.000242127035993855 0.0835826421996247"
        rpy="0 0 0" />
      <mass
        value="0.0205046589058927" />
      <inertia
        ixx="2.37671048423346E-05"
        ixy="-1.29072575162348E-08"
        ixz="-6.43764479926857E-08"
        iyy="1.27843040563581E-05"
        iyz="9.82907716155009E-08"
        izz="1.20351729261164E-05" />
    </inertial>
    <visual>
      <origin
        xyz="0 0 0"
        rpy="0 0 0" />
      <geometry>
        <mesh
          filename="package://inspire_hand_description/meshes/left/left_palm_2.STL" />
      </geometry>
      <material
        name="">
        <color
          rgba="1 1 1 1" />
      </material>
    </visual>
    <collision>
      <origin
        xyz="0 0 0"
        rpy="0 0 0" />
      <geometry>
        <mesh
          filename="package://inspire_hand_description/meshes/left/left_palm_2.STL" />
      </geometry>
    </collision>
  </link>
  <joint
    name="left_palm_2_joint"
    type="fixed">
    <origin
      xyz="0 0 0"
      rpy="0 0 0" />
    <parent
      link="left_palm_1" />
    <child
      link="left_palm_2" />
    <axis
      xyz="0 0 0" />
  </joint>
  <link
    name="left_palm_force_sensor">
    <inertial>
      <origin
        xyz="-0.00012009333519819 0.000717297413646942 -0.000692889069965077"
        rpy="0 0 0" />
      <mass
        value="0.00240886556268154" />
      <inertia
        ixx="1.79237847416138E-07"
        ixy="-3.62335250995994E-10"
        ixz="2.06838829667416E-10"
        iyy="5.01887324843563E-07"
        iyz="-4.23537057624356E-10"
        izz="6.80017237748538E-07" />
    </inertial>
    <visual>
      <origin
        xyz="0 0 0"
        rpy="0 0 0" />
      <geometry>
        <mesh
          filename="package://inspire_hand_description/meshes/left/left_palm_force_sensor.STL" />
      </geometry>
      <material
        name="">
        <color
          rgba="0.25 0.25 0.25 1" />
      </material>
    </visual>
    <collision>
      <origin
        xyz="0 0 0"
        rpy="0 0 0" />
      <geometry>
        <mesh
          filename="package://inspire_hand_description/meshes/left/left_palm_force_sensor.STL" />
      </geometry>
    </collision>
  </link>
  <joint
    name="left_palm_force_sensor_joint"
    type="fixed">
    <origin
      xyz="0.012296 -0.00036819 0.088601"
      rpy="1.5708 0 1.5708" />
    <parent
      link="left_palm_1" />
    <child
      link="left_palm_force_sensor" />
    <axis
      xyz="0 0 0" />
  </joint>
</robot>
