<?xml version="1.0" encoding="utf-8"?>
<!-- This URDF was automatically created by SolidWorks to URDF Exporter! Originally created by Stephen Brawner (brawner@gmail.com) 
     Commit Version: 1.6.0-4-g7f85cfe  Build Version: 1.6.7995.38578
     For more information, please see http://wiki.ros.org/sw_urdf_exporter -->
<robot name="RH56E2_R_2025_9_11">
  <!-- Dummy link to avoid KDL warning about root link inertia -->
  <link name="base_footprint"/>
  <joint name="base_footprint_to_base" type="fixed">
    <parent link="base_footprint"/>
    <child link="base_link"/>
    <origin xyz="0 0 0" rpy="0 0 0"/>
  </joint>
  <link
    name="base_link">
    <inertial>
      <origin
        xyz="0.000585306500185456 4.36854347835025E-08 -0.018822662550448"
        rpy="0 0 0" />
      <mass
        value="0.090" />
      <inertia
        ixx="2.78685380929126E-05"
        ixy="4.78139504897991E-11"
        ixz="-3.96465915290869E-08"
        iyy="2.67805393378652E-05"
        iyz="1.05835026288552E-11"
        izz="3.64886767005748E-05" />
    </inertial>
    <visual>
      <origin
        xyz="0 0 0"
        rpy="0 0 0" />
      <geometry>
        <mesh
          filename="package://inspire_hand_description/meshes/right/base_link.STL" />
      </geometry>
      <material
        name="">
        <color
          rgba="1 1 1 1" />
      </material>
    </visual>
    <collision>
      <origin
        xyz="0 0 0"
        rpy="0 0 0" />
      <geometry>
        <mesh
          filename="package://inspire_hand_description/meshes/right/base_link.STL" />
      </geometry>
    </collision>
  </link>
  <link
    name="right_palm_1">
    <inertial>
      <origin
        xyz="-0.00625 0.0022299999999999998 0.0689"
        rpy="0 0 0" />
      <mass
        value="0.38382" />
      <inertia
        ixx="0.00054913744"
        ixy="-4.42438e-06"
        ixz="2.9859009999999997e-05"
        iyy="0.00040036048"
        iyz="9.570770000000001e-06"
        izz="0.00022521596" />
    </inertial>
    <visual>
      <origin
        xyz="0 0 0"
        rpy="0 0 0" />
      <geometry>
        <mesh
          filename="package://inspire_hand_description/meshes/right/right_palm_1.STL" />
      </geometry>
      <material
        name="">
        <color
          rgba="0.25 0.25 0.25 1" />
      </material>
    </visual>
    <collision>
      <origin
        xyz="0 0 0"
        rpy="0 0 0" />
      <geometry>
        <mesh
          filename="package://inspire_hand_description/meshes/right/right_palm_1.STL" />
      </geometry>
    </collision>
  </link>
  <joint
    name="right_palm_1_joint"
    type="fixed">
    <origin
      xyz="0 0 -0.0305"
      rpy="3.1416 0 0" />
    <parent
      link="base_link" />
    <child
      link="right_palm_1" />
    <axis
      xyz="0 0 0" />
  </joint>
  <link
    name="right_palm_2">
    <inertial>
      <origin
        xyz="-0.0282100608260238 0.000132227033478396 0.0839719055779739"
        rpy="0 0 0" />
      <mass
        value="0.0205048839537772" />
      <inertia
        ixx="2.37673054390923E-05"
        ixy="-1.16564699359491E-08"
        ixz="-5.54590775737826E-08"
        iyy="1.27806531035507E-05"
        iyz="1.11375407726514E-07"
        izz="1.20388397724151E-05" />
    </inertial>
    <visual>
      <origin
        xyz="0 0 0"
        rpy="0 0 0" />
      <geometry>
        <mesh
          filename="package://inspire_hand_description/meshes/right/right_palm_2.STL" />
      </geometry>
      <material
        name="">
        <color
          rgba="1 1 1 1" />
      </material>
    </visual>
    <collision>
      <origin
        xyz="0 0 0"
        rpy="0 0 0" />
      <geometry>
        <mesh
          filename="package://inspire_hand_description/meshes/right/right_palm_2.STL" />
      </geometry>
    </collision>
  </link>
  <joint
    name="right_palm_2_joint"
    type="fixed">
    <origin
      xyz="0 0 0"
      rpy="0 0 0" />
    <parent
      link="right_palm_1" />
    <child
      link="right_palm_2" />
    <axis
      xyz="0 0 0" />
  </joint>
  <link
    name="right_palm_force_sensor">
    <inertial>
      <origin
        xyz="0.000120426998705993 0.000717269735097647 -0.000692893490077784"
        rpy="0 0 0" />
      <mass
        value="0.00240887838334331" />
      <inertia
        ixx="1.79240988219058E-07"
        ixy="3.52975851762018E-10"
        ixz="-2.06008106501924E-10"
        iyy="5.01925283180791E-07"
        iyz="-4.23311043076944E-10"
        izz="6.80058313221634E-07" />
    </inertial>
    <visual>
      <origin
        xyz="0 0 0"
        rpy="0 0 0" />
      <geometry>
        <mesh
          filename="package://inspire_hand_description/meshes/right/right_palm_force_sensor.STL" />
      </geometry>
      <material
        name="">
        <color
          rgba="0.25 0.25 0.25 1" />
      </material>
    </visual>
    <collision>
      <origin
        xyz="0 0 0"
        rpy="0 0 0" />
      <geometry>
        <mesh
          filename="package://inspire_hand_description/meshes/right/right_palm_force_sensor.STL" />
      </geometry>
    </collision>
  </link>
  <joint
    name="right_palm_force_sensor_joint"
    type="fixed">
    <origin
      xyz="0.012296 0.00036819 0.089101"
      rpy="1.5708 0 1.5708" />
    <parent
      link="right_palm_1" />
    <child
      link="right_palm_force_sensor" />
    <axis
      xyz="0 0 0" />
  </joint>
  <link
    name="right_thumb_1">
    <inertial>
      <origin
        xyz="0.00067 0.004940000000000001 -0.00671"
        rpy="0 0 0" />
      <mass
        value="0.01537" />
      <inertia
        ixx="9.7931e-07"
        ixy="-6.197e-08"
        ixz="-4.9e-09"
        iyy="6.735399999999999e-07"
        iyz="-3.6289999999999996e-08"
        izz="8.6359e-07" />
    </inertial>
    <visual>
      <origin
        xyz="0 0 0"
        rpy="0 0 0" />
      <geometry>
        <mesh
          filename="package://inspire_hand_description/meshes/right/right_thumb_1.STL" />
      </geometry>
      <material
        name="">
        <color
          rgba="1 1 1 1" />
      </material>
    </visual>
    <collision>
      <origin
        xyz="0 0 0"
        rpy="0 0 0" />
      <geometry>
        <mesh
          filename="package://inspire_hand_description/meshes/right/right_thumb_1.STL" />
      </geometry>
    </collision>
  </link>
  <joint
    name="right_thumb_1_joint"
    type="revolute">
    <origin
      xyz="0.02101 -0.0269 -0.0826"
      rpy="-3.1416 0 0" />
    <parent
      link="base_link" />
    <child
      link="right_thumb_1" />
    <axis
      xyz="0 0 -1" />
    <limit
      lower="0"
      upper="1.658"
      effort="1"
      velocity="2" />
  </joint>
  <link
    name="right_thumb_2">
    <inertial>
      <origin
        xyz="-0.03301 0.013460000000000001 0.00542"
        rpy="0 0 0" />
      <mass
        value="0.11034000000000001" />
      <inertia
        ixx="1.996898e-05"
        ixy="1.123516e-05"
        ixz="-3.96656e-06"
        iyy="3.366305e-05"
        iyz="1.22531e-06"
        izz="4.2347589999999993e-05" />
    </inertial>
    <visual>
      <origin
        xyz="0 0 0"
        rpy="0 0 0" />
      <geometry>
        <mesh
          filename="package://inspire_hand_description/meshes/right/right_thumb_2.STL" />
      </geometry>
      <material
        name="">
        <color
          rgba="0.25 0.25 0.25 1" />
      </material>
    </visual>
    <collision>
      <origin
        xyz="0 0 0"
        rpy="0 0 0" />
      <geometry>
        <mesh
          filename="package://inspire_hand_description/meshes/right/right_thumb_2.STL" />
      </geometry>
    </collision>
  </link>
  <joint
    name="right_thumb_2_joint"
    type="revolute">
    <origin
      xyz="0.013438 0.012862 -0.0076"
      rpy="1.5708 0 -1.5708" />
    <parent
      link="right_thumb_1" />
    <child
      link="right_thumb_2" />
    <axis
      xyz="0.17365 0 -0.98481" />
    <limit
      lower="0"
      upper="0.62"
      effort="1"
      velocity="2" />
  </joint>
  <link
    name="right_thumb_3">
    <inertial>
      <origin
        xyz="-0.01108 0.00155 0.011529999999999999"
        rpy="0 0 0" />
      <mass
        value="0.01779" />
      <inertia
        ixx="3.09353e-06"
        ixy="3.9120999999999997e-07"
        ixz="1.2929999999999999e-08"
        iyy="2.57591e-06"
        iyz="-7.61e-09"
        izz="3.32754e-06" />
    </inertial>
    <visual>
      <origin
        xyz="0 0 0"
        rpy="0 0 0" />
      <geometry>
        <mesh
          filename="package://inspire_hand_description/meshes/right/right_thumb_3.STL" />
      </geometry>
      <material
        name="">
        <color
          rgba="0.25 0.25 0.25 1" />
      </material>
    </visual>
    <collision>
      <origin
        xyz="0 0 0"
        rpy="0 0 0" />
      <geometry>
        <mesh
          filename="package://inspire_hand_description/meshes/right/right_thumb_3.STL" />
      </geometry>
    </collision>
  </link>
  <joint
    name="right_thumb_3_joint"
    type="revolute">
    <origin
      xyz="-0.052954 0.032799 -0.0093372"
      rpy="0 0 0" />
    <parent
      link="right_thumb_2" />
    <child
      link="right_thumb_3" />
    <axis
      xyz="0.17365 0 -0.98481" />
    <limit
      lower="0"
      upper="0.5410520681182421"
      effort="1"
      velocity="2" />
    <mimic
        joint="right_thumb_2_joint"
        multiplier="0.8392"
        offset="0" />  
  </joint>
  <link
    name="right_thumb_force_sensor_2">
    <inertial>
      <origin
        xyz="6.77003975447232E-05 -0.000236985202900622 -0.000558267741289802"
        rpy="0 0 0" />
      <mass
        value="0.000119024197892742" />
      <inertia
        ixx="1.02244976989544E-09"
        ixy="-6.74105007093921E-13"
        ixz="1.14255898493093E-12"
        iyy="9.97039736805973E-10"
        iyz="8.16377458719893E-12"
        izz="1.99065057325864E-09" />
    </inertial>
    <visual>
      <origin
        xyz="0 0 0"
        rpy="0 0 0" />
      <geometry>
        <mesh
          filename="package://inspire_hand_description/meshes/right/right_thumb_force_sensor_2.STL" />
      </geometry>
      <material
        name="">
        <color
          rgba="0.25 0.25 0.25 1" />
      </material>
    </visual>
    <collision>
      <origin
        xyz="0 0 0"
        rpy="0 0 0" />
      <geometry>
        <mesh
          filename="package://inspire_hand_description/meshes/right/right_thumb_force_sensor_2.STL" />
      </geometry>
    </collision>
  </link>
  <joint
    name="right_thumb_force_sensor_2_joint"
    type="fixed">
    <origin
      xyz="-0.0080057 0.016443 0.0096921"
      rpy="-1.041 1.3851 -0.037357" />
    <parent
      link="right_thumb_3" />
    <child
      link="right_thumb_force_sensor_2" />
    <axis
      xyz="0 0 0" />
  </joint>
  <link
    name="right_thumb_4">
    <inertial>
      <origin
        xyz="-0.01264 0.007730000000000001 0.0105"
        rpy="0 0 0" />
      <mass
        value="0.00766" />
      <inertia
        ixx="1.15326e-06"
        ixy="1.6573e-07"
        ixz="-4.0000000000000004e-11"
        iyy="5.7535e-07"
        iyz="-7e-11"
        izz="1.15929e-06" />
    </inertial>
    <visual>
      <origin
        xyz="0 0 0"
        rpy="0 0 0" />
      <geometry>
        <mesh
          filename="package://inspire_hand_description/meshes/right/right_thumb_4.STL" />
      </geometry>
      <material
        name="">
        <color
          rgba="0.25 0.25 0.25 1" />
      </material>
    </visual>
    <collision>
      <origin
        xyz="0 0 0"
        rpy="0 0 0" />
      <geometry>
        <mesh
          filename="package://inspire_hand_description/meshes/right/right_thumb_4.STL" />
      </geometry>
    </collision>
  </link>
  <joint
    name="right_thumb_4_joint"
    type="revolute">
    <origin
      xyz="-0.01865 0.013373 -0.0022731"
      rpy="0 0 0" />
    <parent
      link="right_thumb_3" />
    <child
      link="right_thumb_4" />
    <axis
      xyz="0.17365 0 -0.98481" />
    <limit
      lower="0"
      upper="0.45553093477052004"
      effort="1"
      velocity="2" />
    <mimic
        joint="right_thumb_3_joint"
        multiplier="0.891"
        offset="0" /> 
  </joint>
  <link
    name="right_thumb_force_sensor_3">
    <inertial>
      <origin
        xyz="-2.5107148976522E-07 -0.000696658150200258 -0.000425102019813703"
        rpy="0 0 0" />
      <mass
        value="0.000169893832350009" />
      <inertia
        ixx="3.91696226730881E-09"
        ixy="2.31955134193414E-14"
        ixz="-2.76639995099676E-13"
        iyy="1.41883536310886E-09"
        iyz="1.72950699351222E-10"
        izz="5.29525439677813E-09" />
    </inertial>
    <visual>
      <origin
        xyz="0 0 0"
        rpy="0 0 0" />
      <geometry>
        <mesh
          filename="package://inspire_hand_description/meshes/right/right_thumb_force_sensor_3.STL" />
      </geometry>
      <material
        name="">
        <color
          rgba="0.25 0.25 0.25 1" />
      </material>
    </visual>
    <collision>
      <origin
        xyz="0 0 0"
        rpy="0 0 0" />
      <geometry>
        <mesh
          filename="package://inspire_hand_description/meshes/right/right_thumb_force_sensor_3.STL" />
      </geometry>
    </collision>
  </link>
  <joint
    name="right_thumb_force_sensor_3_joint"
    type="fixed">
    <origin
      xyz="-0.0076345 0.020486 0.0088067"
      rpy="-0.64083 1.3963 4.2914E-05" />
    <parent
      link="right_thumb_4" />
    <child
      link="right_thumb_force_sensor_3" />
    <axis
      xyz="0 0 0" />
  </joint>
  <link
    name="right_thumb_force_sensor_4">
    <inertial>
      <origin
        xyz="-1.51405730541843E-06 0.000421607186812417 -0.000751976299815514"
        rpy="0 0 0" />
      <mass
        value="1.66991205082657E-05" />
      <inertia
        ixx="2.25773453689085E-11"
        ixy="2.49446980591774E-15"
        ixz="5.29906678520533E-15"
        iyy="2.30774509490308E-11"
        iyz="-1.74397529562637E-13"
        izz="4.31637430427716E-11" />
    </inertial>
    <visual>
      <origin
        xyz="0 0 0"
        rpy="0 0 0" />
      <geometry>
        <mesh
          filename="package://inspire_hand_description/meshes/right/right_thumb_force_sensor_4.STL" />
      </geometry>
      <material
        name="">
        <color
          rgba="0.25 0.25 0.25 1" />
      </material>
    </visual>
    <collision>
      <origin
        xyz="0 0 0"
        rpy="0 0 0" />
      <geometry>
        <mesh
          filename="package://inspire_hand_description/meshes/right/right_thumb_force_sensor_4.STL" />
      </geometry>
    </collision>
  </link>
  <joint
    name="right_thumb_force_sensor_4_joint"
    type="fixed">
    <origin
      xyz="-0.01883 0.027914 0.0068326"
      rpy="-1.7492 1.3963 0.0014317" />
    <parent
      link="right_thumb_4" />
    <child
      link="right_thumb_force_sensor_4" />
    <axis
      xyz="0 0 0" />
  </joint>
  <link
    name="right_thumb_force_sensor_1">
    <inertial>
      <origin
        xyz="0.000311386521466117 -9.39437134603871E-05 -0.000511449075416445"
        rpy="0 0 0" />
      <mass
        value="0.000234345870584151" />
      <inertia
        ixx="6.81918457897941E-09"
        ixy="-1.59551743941395E-10"
        ixz="1.7219245024005E-11"
        iyy="2.92367232191599E-09"
        iyz="1.8000053919482E-10"
        izz="9.68890809981099E-09" />
    </inertial>
    <visual>
      <origin
        xyz="0 0 0"
        rpy="0 0 0" />
      <geometry>
        <mesh
          filename="package://inspire_hand_description/meshes/right/right_thumb_force_sensor_1.STL" />
      </geometry>
      <material
        name="">
        <color
          rgba="0.25 0.25 0.25 1" />
      </material>
    </visual>
    <collision>
      <origin
        xyz="0 0 0"
        rpy="0 0 0" />
      <geometry>
        <mesh
          filename="package://inspire_hand_description/meshes/right/right_thumb_force_sensor_1.STL" />
      </geometry>
    </collision>
  </link>
  <joint
    name="right_thumb_force_sensor_1_joint"
    type="fixed">
    <origin
      xyz="-0.023424 0.033251 0.007073"
      rpy="-0.99905 1.4338 0.13409" />
    <parent
      link="right_thumb_2" />
    <child
      link="right_thumb_force_sensor_1" />
    <axis
      xyz="0 0 0" />
  </joint>
  <link
    name="right_index_1">
    <inertial>
      <origin
        xyz="0.00132 0.01078 0.00805"
        rpy="0 0 0" />
      <mass
        value="0.018690000000000002" />
      <inertia
        ixx="3.59962e-06"
        ixy="-4.1645999999999996e-07"
        ixz="-1.6599999999999999e-09"
        iyy="1.20603e-06"
        iyz="-6.3e-10"
        izz="3.79687e-06" />
    </inertial>
    <visual>
      <origin
        xyz="0 0 0"
        rpy="0 0 0" />
      <geometry>
        <mesh
          filename="package://inspire_hand_description/meshes/right/right_index_1.STL" />
      </geometry>
      <material
        name="">
        <color
          rgba="0.25 0.25 0.25 1" />
      </material>
    </visual>
    <collision>
      <origin
        xyz="0 0 0"
        rpy="0 0 0" />
      <geometry>
        <mesh
          filename="package://inspire_hand_description/meshes/right/right_index_1.STL" />
      </geometry>
    </collision>
  </link>
  <joint
    name="right_index_1_joint"
    type="revolute">
    <origin
      xyz="0.00056467 -0.038679 -0.1564"
      rpy="-1.6057 0 0" />
    <parent
      link="base_link" />
    <child
      link="right_index_1" />
    <axis
      xyz="0 0 -1" />
    <limit
      lower="0"
      upper="1.4381"
      effort="1"
      velocity="1" />
  </joint>
  <link
    name="right_index_2">
    <inertial>
      <origin
        xyz="-0.00016 0.0177 0.008"
        rpy="0 0 0" />
      <mass
        value="0.01102" />
      <inertia
        ixx="2.32185e-06"
        ixy="-5.6428e-07"
        ixz="9e-11"
        iyy="4.134e-07"
        iyz="3.9e-10"
        izz="2.4238400000000002e-06" />
    </inertial>
    <visual>
      <origin
        xyz="0 0 0"
        rpy="0 0 0" />
      <geometry>
        <mesh
          filename="package://inspire_hand_description/meshes/right/right_index_2.STL" />
      </geometry>
      <material
        name="">
        <color
          rgba="0.25 0.25 0.25 1" />
      </material>
    </visual>
    <collision>
      <origin
        xyz="0 0 0"
        rpy="0 0 0" />
      <geometry>
        <mesh
          filename="package://inspire_hand_description/meshes/right/right_index_2.STL" />
      </geometry>
    </collision>
  </link>
  <joint
    name="right_index_2_joint"
    type="revolute">
    <origin
      xyz="0.0034259 0.032596 0.00055"
      rpy="0 0 0" />
    <parent
      link="right_index_1" />
    <child
      link="right_index_2" />
    <axis
      xyz="0 0 -1" />
    <limit
      lower="0"
      upper="1.476374"
      effort="1"
      velocity="1" />
    <mimic
        joint="right_index_1_joint"
        multiplier="1.0843"
        offset="0" />   
  </joint>
  <link
    name="right_index_force_sensor_2">
    <inertial>
      <origin
        xyz="3.91105790090857E-06 0.000206428506730846 -0.000722888656592813"
        rpy="0 0 0" />
      <mass
        value="0.000255748458180208" />
      <inertia
        ixx="4.79878645065383E-09"
        ixy="-8.64076408119862E-11"
        ixz="-1.50330115198994E-12"
        iyy="2.43958893457375E-09"
        iyz="-3.05132448820246E-11"
        izz="7.12570334555721E-09" />
    </inertial>
    <visual>
      <origin
        xyz="0 0 0"
        rpy="0 0 0" />
      <geometry>
        <mesh
          filename="package://inspire_hand_description/meshes/right/right_index_force_sensor_2.STL" />
      </geometry>
      <material
        name="">
        <color
          rgba="0.25 0.25 0.25 1" />
      </material>
    </visual>
    <collision>
      <origin
        xyz="0 0 0"
        rpy="0 0 0" />
      <geometry>
        <mesh
          filename="package://inspire_hand_description/meshes/right/right_index_force_sensor_2.STL" />
      </geometry>
    </collision>
  </link>
  <joint
    name="right_index_force_sensor_2_joint"
    type="fixed">
    <origin
      xyz="0.0081655 0.037446 0.0060795"
      rpy="1.5708 1.5337 1.222" />
    <parent
      link="right_index_2" />
    <child
      link="right_index_force_sensor_2" />
    <axis
      xyz="0 0 0" />
  </joint>
  <link
    name="right_index_force_sensor_3">
    <inertial>
      <origin
        xyz="-2.48722057788475E-05 -0.000345285689256153 -0.00133800038179009"
        rpy="0 0 0" />
      <mass
        value="6.79646984897729E-05" />
      <inertia
        ixx="1.31974821284448E-10"
        ixy="5.65060068039534E-12"
        ixz="7.79117122469888E-13"
        iyy="2.53430134807533E-10"
        iyz="9.12198063131294E-12"
        izz="2.8053351791299E-10" />
    </inertial>
    <visual>
      <origin
        xyz="0 0 0"
        rpy="0 0 0" />
      <geometry>
        <mesh
          filename="package://inspire_hand_description/meshes/right/right_index_force_sensor_3.STL" />
      </geometry>
      <material
        name="">
        <color
          rgba="0.25 0.25 0.25 1" />
      </material>
    </visual>
    <collision>
      <origin
        xyz="0 0 0"
        rpy="0 0 0" />
      <geometry>
        <mesh
          filename="package://inspire_hand_description/meshes/right/right_index_force_sensor_3.STL" />
      </geometry>
    </collision>
  </link>
  <joint
    name="right_index_force_sensor_3_joint"
    type="fixed">
    <origin
      xyz="0.0086237 0.052572 0.0060954"
      rpy="1.5708 1.5252 2.2692" />
    <parent
      link="right_index_2" />
    <child
      link="right_index_force_sensor_3" />
    <axis
      xyz="0 0 0" />
  </joint>
  <link
    name="right_index_force_sensor_1">
    <inertial>
      <origin
        xyz="4.50639917341789E-06 0.000116571661332499 -0.000567443126962344"
        rpy="0 0 0" />
      <mass
        value="0.00020277926206694" />
      <inertia
        ixx="3.38028798502951E-09"
        ixy="-5.04640338896753E-11"
        ixz="-2.15701714440208E-13"
        iyy="1.96412698995832E-09"
        iyz="-5.48195334354602E-12"
        izz="5.28079732652295E-09" />
    </inertial>
    <visual>
      <origin
        xyz="0 0 0"
        rpy="0 0 0" />
      <geometry>
        <mesh
          filename="package://inspire_hand_description/meshes/right/right_index_force_sensor_1.STL" />
      </geometry>
      <material
        name="">
        <color
          rgba="0.25 0.25 0.25 1" />
      </material>
    </visual>
    <collision>
      <origin
        xyz="0 0 0"
        rpy="0 0 0" />
      <geometry>
        <mesh
          filename="package://inspire_hand_description/meshes/right/right_index_force_sensor_1.STL" />
      </geometry>
    </collision>
  </link>
  <joint
    name="right_index_force_sensor_1_joint"
    type="fixed">
    <origin
      xyz="0.012046 0.019649 0.006651"
      rpy="1.5708 1.5351 1.7829" />
    <parent
      link="right_index_1" />
    <child
      link="right_index_force_sensor_1" />
    <axis
      xyz="0 0 0" />
  </joint>
  <link
    name="right_middle_1">
    <inertial>
      <origin
        xyz="0.0013700000000000001 0.011009999999999999 0.008060000000000001"
        rpy="0 0 0" />
      <mass
        value="0.01866" />
      <inertia
        ixx="3.59341e-06"
        ixy="-4.0058999999999996e-07"
        ixz="-1.64e-09"
        iyy="1.20028e-06"
        iyz="-1.21e-09"
        izz="3.7852399999999996e-06" />
    </inertial>
    <visual>
      <origin
        xyz="0 0 0"
        rpy="0 0 0" />
      <geometry>
        <mesh
          filename="package://inspire_hand_description/meshes/right/right_middle_1.STL" />
      </geometry>
      <material
        name="">
        <color
          rgba="0.25 0.25 0.25 1" />
      </material>
    </visual>
    <collision>
      <origin
        xyz="0 0 0"
        rpy="0 0 0" />
      <geometry>
        <mesh
          filename="package://inspire_hand_description/meshes/right/right_middle_1.STL" />
      </geometry>
    </collision>
  </link>
  <joint
    name="right_middle_1_joint"
    type="revolute">
    <origin
      xyz="0.00056467 -0.0171 -0.157"
      rpy="-1.5708 0 0" />
    <parent
      link="base_link" />
    <child
      link="right_middle_1" />
    <axis
      xyz="0 0 -1" />
    <limit
      lower="0"
      upper="1.4381"
      effort="1"
      velocity="1" />
  </joint>
  <link
    name="right_middle_2">
    <inertial>
      <origin
        xyz="0.0019 0.02314 0.00802"
        rpy="0 0 0" />
      <mass
        value="0.01767" />
      <inertia
        ixx="4.63728e-06"
        ixy="-1.35163e-06"
        ixz="2.92e-09"
        iyy="9.821e-07"
        iyz="1.151e-08"
        izz="5.00365e-06" />
    </inertial>
    <visual>
      <origin
        xyz="0 0 0"
        rpy="0 0 0" />
      <geometry>
        <mesh
          filename="package://inspire_hand_description/meshes/right/right_middle_2.STL" />
      </geometry>
      <material
        name="">
        <color
          rgba="0.25 0.25 0.25 1" />
      </material>
    </visual>
    <collision>
      <origin
        xyz="0 0 0"
        rpy="0 0 0" />
      <geometry>
        <mesh
          filename="package://inspire_hand_description/meshes/right/right_middle_2.STL" />
      </geometry>
    </collision>
  </link>
  <joint
    name="right_middle_2_joint"
    type="revolute">
    <origin
      xyz="0.0034259 0.032596 0.00055"
      rpy="0 0 0" />
    <parent
      link="right_middle_1" />
    <child
      link="right_middle_2" />
    <axis
      xyz="0 0 -1" />
    <limit
      lower="0"
      upper="1.476374"
      effort="1"
      velocity="1" />
    <mimic
        joint="right_middle_1_joint"
        multiplier="1.0843"
        offset="0" />
  </joint>
  <link
    name="right_middle_force_sensor_2">
    <inertial>
      <origin
        xyz="-3.55652627983399E-07 2.88666331397097E-05 -0.000722235489778011"
        rpy="0 0 0" />
      <mass
        value="0.00026259331441686" />
      <inertia
        ixx="5.0422606271269E-09"
        ixy="3.96627458519253E-13"
        ixz="-3.26041478710841E-14"
        iyy="2.56807850635635E-09"
        iyz="3.5373620870123E-12"
        izz="7.49563436241948E-09" />
    </inertial>
    <visual>
      <origin
        xyz="0 0 0"
        rpy="0 0 0" />
      <geometry>
        <mesh
          filename="package://inspire_hand_description/meshes/right/right_middle_force_sensor_2.STL" />
      </geometry>
      <material
        name="">
        <color
          rgba="0.25 0.25 0.25 1" />
      </material>
    </visual>
    <collision>
      <origin
        xyz="0 0 0"
        rpy="0 0 0" />
      <geometry>
        <mesh
          filename="package://inspire_hand_description/meshes/right/right_middle_force_sensor_2.STL" />
      </geometry>
    </collision>
  </link>
  <joint
    name="right_middle_force_sensor_2_joint"
    type="fixed">
    <origin
      xyz="0.0090859 0.040963 0.0061003"
      rpy="0.37285 1.5708 0" />
    <parent
      link="right_middle_2" />
    <child
      link="right_middle_force_sensor_2" />
    <axis
      xyz="0 0 0" />
  </joint>
  <link
    name="right_middle_force_sensor_3">
    <inertial>
      <origin
        xyz="6.04731043574169E-08 -0.00036544534557964 -0.00127683945630336"
        rpy="0 0 0" />
      <mass
        value="6.64914575467581E-05" />
      <inertia
        ixx="1.27227764572837E-10"
        ixy="1.00476590749342E-14"
        ixz="8.5788062829599E-15"
        iyy="2.43691164484047E-10"
        iyz="7.61272996067338E-12"
        izz="2.75875170563041E-10" />
    </inertial>
    <visual>
      <origin
        xyz="0 0 0"
        rpy="0 0 0" />
      <geometry>
        <mesh
          filename="package://inspire_hand_description/meshes/right/right_middle_force_sensor_3.STL" />
      </geometry>
      <material
        name="">
        <color
          rgba="0.25 0.25 0.25 1" />
      </material>
    </visual>
    <collision>
      <origin
        xyz="0 0 0"
        rpy="0 0 0" />
      <geometry>
        <mesh
          filename="package://inspire_hand_description/meshes/right/right_middle_force_sensor_3.STL" />
      </geometry>
    </collision>
  </link>
  <joint
    name="right_middle_force_sensor_3_joint"
    type="fixed">
    <origin
      xyz="0.0098294 0.056051 0.0061006"
      rpy="-0.67435 1.5708 0" />
    <parent
      link="right_middle_2" />
    <child
      link="right_middle_force_sensor_3" />
    <axis
      xyz="0 0 0" />
  </joint>
  <link
    name="right_middle_force_sensor_1">
    <inertial>
      <origin
        xyz="3.42843697213185E-07 0.000116657509605197 -0.000567442695803486"
        rpy="0 0 0" />
      <mass
        value="0.000202779388301744" />
      <inertia
        ixx="3.38208410519618E-09"
        ixy="1.87569574369712E-13"
        ixz="-1.99647221364038E-14"
        iyy="1.96233204624223E-09"
        iyz="-5.48580562274486E-12"
        izz="5.2807983995112E-09" />
    </inertial>
    <visual>
      <origin
        xyz="0 0 0"
        rpy="0 0 0" />
      <geometry>
        <mesh
          filename="package://inspire_hand_description/meshes/right/right_middle_force_sensor_1.STL" />
      </geometry>
      <material
        name="">
        <color
          rgba="0.25 0.25 0.25 1" />
      </material>
    </visual>
    <collision>
      <origin
        xyz="0 0 0"
        rpy="0 0 0" />
      <geometry>
        <mesh
          filename="package://inspire_hand_description/meshes/right/right_middle_force_sensor_1.STL" />
      </geometry>
    </collision>
  </link>
  <joint
    name="right_middle_force_sensor_1_joint"
    type="fixed">
    <origin
      xyz="0.012046 0.019649 0.006651"
      rpy="-0.21209 1.5708 0" />
    <parent
      link="right_middle_1" />
    <child
      link="right_middle_force_sensor_1" />
    <axis
      xyz="0 0 0" />
  </joint>
  <link
    name="right_ring_1">
    <inertial>
      <origin
        xyz="0.0011899999999999999 0.01036 0.00861"
        rpy="0 0 0" />
      <mass
        value="0.018690000000000002" />
      <inertia
        ixx="3.60961e-06"
        ixy="-3.8725e-07"
        ixz="-2.1949999999999998e-08"
        iyy="1.20307e-06"
        iyz="-1.3659e-07"
        izz="3.78952e-06" />
    </inertial>
    <visual>
      <origin
        xyz="0 0 0"
        rpy="0 0 0" />
      <geometry>
        <mesh
          filename="package://inspire_hand_description/meshes/right/right_ring_1.STL" />
      </geometry>
      <material
        name="">
        <color
          rgba="0.25 0.25 0.25 1" />
      </material>
    </visual>
    <collision>
      <origin
        xyz="0 0 0"
        rpy="0 0 0" />
      <geometry>
        <mesh
          filename="package://inspire_hand_description/meshes/right/right_ring_1.STL" />
      </geometry>
    </collision>
  </link>
  <joint
    name="right_ring_1_joint"
    type="revolute">
    <origin
      xyz="0.00056467 0.0045302 -0.15683"
      rpy="-1.5184 0 0" />
    <parent
      link="base_link" />
    <child
      link="right_ring_1" />
    <axis
      xyz="0 0 -1" />
    <limit
      lower="0"
      upper="1.4381"
      effort="1"
      velocity="1" />
  </joint>
  <link
    name="right_ring_2">
    <inertial>
      <origin
        xyz="-0.00057 0.01725 0.00891"
        rpy="0 0 0" />
      <mass
        value="0.01102" />
      <inertia
        ixx="2.3471100000000002e-06"
        ixy="-5.196000000000001e-07"
        ixz="-2.702e-08"
        iyy="3.9493e-07"
        iyz="-1.0668000000000001e-07"
        izz="2.41823e-06" />
    </inertial>
    <visual>
      <origin
        xyz="0 0 0"
        rpy="0 0 0" />
      <geometry>
        <mesh
          filename="package://inspire_hand_description/meshes/right/right_ring_2.STL" />
      </geometry>
      <material
        name="">
        <color
          rgba="0.25 0.25 0.25 1" />
      </material>
    </visual>
    <collision>
      <origin
        xyz="0 0 0"
        rpy="0 0 0" />
      <geometry>
        <mesh
          filename="package://inspire_hand_description/meshes/right/right_ring_2.STL" />
      </geometry>
    </collision>
  </link>
  <joint
    name="right_ring_2_joint"
    type="revolute">
    <origin
      xyz="0.0034259 0.032596 0.00055"
      rpy="0 0 0" />
    <parent
      link="right_ring_1" />
    <child
      link="right_ring_2" />
    <axis
      xyz="0 0 -1" />
    <limit
      lower="0"
      upper="1.476374"
      effort="1"
      velocity="1" />
    <mimic
        joint="right_ring_1_joint"
        multiplier="1.0843"
        offset="0" />
  </joint>
  <link
    name="right_ring_force_sensor_2">
    <inertial>
      <origin
        xyz="-1.52436836102507E-05 0.000205901966578867 -0.000722888420899154"
        rpy="0 0 0" />
      <mass
        value="0.00025574845564278" />
      <inertia
        ixx="4.79446001367807E-09"
        ixy="1.32867587230573E-10"
        ixz="1.33199694981756E-12"
        iyy="2.44391505492957E-09"
        iyz="-3.05212434039715E-11"
        izz="7.12570290551657E-09" />
    </inertial>
    <visual>
      <origin
        xyz="0 0 0"
        rpy="0 0 0" />
      <geometry>
        <mesh
          filename="package://inspire_hand_description/meshes/right/right_ring_force_sensor_2.STL" />
      </geometry>
      <material
        name="">
        <color
          rgba="0.25 0.25 0.25 1" />
      </material>
    </visual>
    <collision>
      <origin
        xyz="0 0 0"
        rpy="0 0 0" />
      <geometry>
        <mesh
          filename="package://inspire_hand_description/meshes/right/right_ring_force_sensor_2.STL" />
      </geometry>
    </collision>
  </link>
  <joint
    name="right_ring_force_sensor_2_joint"
    type="fixed">
    <origin
      xyz="0.0081655 0.037446 0.0060795"
      rpy="-1.5708 1.5151 -1.9196" />
    <parent
      link="right_ring_2" />
    <child
      link="right_ring_force_sensor_2" />
    <axis
      xyz="0 0 0" />
  </joint>
  <link
    name="right_ring_force_sensor_3">
    <inertial>
      <origin
        xyz="1.45479882125935E-05 -0.000345868482895695 -0.00133799622032654"
        rpy="0 0 0" />
      <mass
        value="6.79650392240318E-05" />
      <inertia
        ixx="1.32268381568451E-10"
        ixy="-8.21005452975136E-12"
        ixz="-2.63862426644721E-13"
        iyy="2.53139744192141E-10"
        iyz="9.15106235580156E-12"
        izz="2.80536243626591E-10" />
    </inertial>
    <visual>
      <origin
        xyz="0 0 0"
        rpy="0 0 0" />
      <geometry>
        <mesh
          filename="package://inspire_hand_description/meshes/right/right_ring_force_sensor_3.STL" />
      </geometry>
      <material
        name="">
        <color
          rgba="0.25 0.25 0.25 1" />
      </material>
    </visual>
    <collision>
      <origin
        xyz="0 0 0"
        rpy="0 0 0" />
      <geometry>
        <mesh
          filename="package://inspire_hand_description/meshes/right/right_ring_force_sensor_3.STL" />
      </geometry>
    </collision>
  </link>
  <joint
    name="right_ring_force_sensor_3_joint"
    type="fixed">
    <origin
      xyz="0.0086237 0.052572 0.0060954"
      rpy="-1.5708 1.5025 -0.87237" />
    <parent
      link="right_ring_2" />
    <child
      link="right_ring_force_sensor_3" />
    <axis
      xyz="0 0 0" />
  </joint>
  <link
    name="right_ring_force_sensor_1">
    <inertial>
      <origin
        xyz="-5.90327958141946E-06 0.000116509445804644 -0.000567443259521558"
        rpy="0 0 0" />
      <mass
        value="0.00020277922338036" />
      <inertia
        ixx="3.37799540185096E-09"
        ixy="7.60796091703614E-11"
        ixz="2.73854397842958E-13"
        iyy="1.96641957767428E-09"
        iyz="-5.47947431188337E-12"
        izz="5.28079735826682E-09" />
    </inertial>
    <visual>
      <origin
        xyz="0 0 0"
        rpy="0 0 0" />
      <geometry>
        <mesh
          filename="package://inspire_hand_description/meshes/right/right_ring_force_sensor_1.STL" />
      </geometry>
      <material
        name="">
        <color
          rgba="0.25 0.25 0.25 1" />
      </material>
    </visual>
    <collision>
      <origin
        xyz="0 0 0"
        rpy="0 0 0" />
      <geometry>
        <mesh
          filename="package://inspire_hand_description/meshes/right/right_ring_force_sensor_1.STL" />
      </geometry>
    </collision>
  </link>
  <joint
    name="right_ring_force_sensor_1_joint"
    type="fixed">
    <origin
      xyz="0.012046 0.019649 0.006651"
      rpy="-1.5708 1.5172 -1.3587" />
    <parent
      link="right_ring_1" />
    <child
      link="right_ring_force_sensor_1" />
    <axis
      xyz="0 0 0" />
  </joint>
  <link
    name="right_little_1">
    <inertial>
      <origin
        xyz="0.0008100000000000001 0.00991 0.00914"
        rpy="0 0 0" />
      <mass
        value="0.018690000000000002" />
      <inertia
        ixx="3.6346399999999997e-06"
        ixy="-3.0236e-07"
        ixz="-3.3420000000000004e-08"
        iyy="1.19929e-06"
        iyz="-2.7369e-07"
        izz="3.76746e-06" />
    </inertial>
    <visual>
      <origin
        xyz="0 0 0"
        rpy="0 0 0" />
      <geometry>
        <mesh
          filename="package://inspire_hand_description/meshes/right/right_little_1.STL" />
      </geometry>
      <material
        name="">
        <color
          rgba="0.25 0.25 0.25 1" />
      </material>
    </visual>
    <collision>
      <origin
        xyz="0 0 0"
        rpy="0 0 0" />
      <geometry>
        <mesh
          filename="package://inspire_hand_description/meshes/right/right_little_1.STL" />
      </geometry>
    </collision>
  </link>
  <joint
    name="right_little_1_joint"
    type="revolute">
    <origin
      xyz="0.00056467 0.025916 -0.15365"
      rpy="-1.4661 0 0" />
    <parent
      link="base_link" />
    <child
      link="right_little_1" />
    <axis
      xyz="0 0 -1" />
    <limit
      lower="0"
      upper="1.4381"
      effort="1"
      velocity="1" />
  </joint>
  <link
    name="right_little_2">
    <inertial>
      <origin
        xyz="-0.00094 0.01672 0.009800000000000001"
        rpy="0 0 0" />
      <mass
        value="0.01166" />
      <inertia
        ixx="2.29937e-06"
        ixy="-4.8052e-07"
        ixz="-5.047e-08"
        iyy="4.6335000000000003e-07"
        iyz="-1.984e-07"
        izz="2.33336e-06" />
    </inertial>
    <visual>
      <origin
        xyz="0 0 0"
        rpy="0 0 0" />
      <geometry>
        <mesh
          filename="package://inspire_hand_description/meshes/right/right_little_2.STL" />
      </geometry>
      <material
        name="">
        <color
          rgba="0.25 0.25 0.25 1" />
      </material>
    </visual>
    <collision>
      <origin
        xyz="0 0 0"
        rpy="0 0 0" />
      <geometry>
        <mesh
          filename="package://inspire_hand_description/meshes/right/right_little_2.STL" />
      </geometry>
    </collision>
  </link>
  <joint
    name="right_little_2_joint"
    type="revolute">
    <origin
      xyz="0.0034259 0.032596 0.00055"
      rpy="0 0 0" />
    <parent
      link="right_little_1" />
    <child
      link="right_little_2" />
    <axis
      xyz="0 0 -1" />
    <limit
      lower="0"
      upper="1.476374"
      effort="1"
      velocity="1" />
    <mimic
        joint="right_little_1_joint"
        multiplier="1.0843"
        offset="0" />  
  </joint>
  <link
    name="right_little_force_sensor_2">
    <inertial>
      <origin
        xyz="1.83850807690678E-05 -0.000118792499944682 -0.000773536639654265"
        rpy="0 0 0" />
      <mass
        value="0.000280265363825451" />
      <inertia
        ixx="5.36105565367507E-09"
        ixy="2.90871023858778E-10"
        ixz="-4.23704440233307E-12"
        iyy="2.78924633862049E-09"
        iyz="3.60734545957643E-11"
        izz="8.01055296833177E-09" />
    </inertial>
    <visual>
      <origin
        xyz="0 0 0"
        rpy="0 0 0" />
      <geometry>
        <mesh
          filename="package://inspire_hand_description/meshes/right/right_little_force_sensor_2.STL" />
      </geometry>
      <material
        name="">
        <color
          rgba="0.25 0.25 0.25 1" />
      </material>
    </visual>
    <collision>
      <origin
        xyz="0 0 0"
        rpy="0 0 0" />
      <geometry>
        <mesh
          filename="package://inspire_hand_description/meshes/right/right_little_force_sensor_2.STL" />
      </geometry>
    </collision>
  </link>
  <joint
    name="right_little_force_sensor_2_joint"
    type="fixed">
    <origin
      xyz="0.0064512 0.027683 0.0061172"
      rpy="-1.5708 1.4597 -1.9127" />
    <parent
      link="right_little_2" />
    <child
      link="right_little_force_sensor_2" />
    <axis
      xyz="0 0 0" />
  </joint>
  <link
    name="right_little_force_sensor_3">
    <inertial>
      <origin
        xyz="6.36863053955425E-05 -0.00043723677420851 -0.00112814037373135"
        rpy="0 0 0" />
      <mass
        value="6.10539921684107E-05" />
      <inertia
        ixx="1.11592356002466E-10"
        ixy="-1.48925479775259E-11"
        ixz="-1.18387481927138E-12"
        iyy="2.17209112811676E-10"
        iyz="8.07880135891959E-12"
        izz="2.52055535156649E-10" />
    </inertial>
    <visual>
      <origin
        xyz="0 0 0"
        rpy="0 0 0" />
      <geometry>
        <mesh
          filename="package://inspire_hand_description/meshes/right/right_little_force_sensor_3.STL" />
      </geometry>
      <material
        name="">
        <color
          rgba="0.25 0.25 0.25 1" />
      </material>
    </visual>
    <collision>
      <origin
        xyz="0 0 0"
        rpy="0 0 0" />
      <geometry>
        <mesh
          filename="package://inspire_hand_description/meshes/right/right_little_force_sensor_3.STL" />
      </geometry>
    </collision>
  </link>
  <joint
    name="right_little_force_sensor_3_joint"
    type="fixed">
    <origin
      xyz="0.0063972 0.042707 0.0061154"
      rpy="-1.5708 1.4336 -0.86551" />
    <parent
      link="right_little_2" />
    <child
      link="right_little_force_sensor_3" />
    <axis
      xyz="0 0 0" />
  </joint>
  <link
    name="right_little_force_sensor_1">
    <inertial>
      <origin
        xyz="-1.21300809558696E-05 0.000116026903212899 -0.000567442994249934"
        rpy="0 0 0" />
      <mass
        value="0.000202779290224811" />
      <inertia
        ixx="3.3658199564233E-09"
        ixy="1.51080971417152E-10"
        ixz="5.66657100478414E-13"
        iyy="1.97859528185445E-09"
        iyz="-5.45672948532718E-12"
        izz="5.28079755559196E-09" />
    </inertial>
    <visual>
      <origin
        xyz="0 0 0"
        rpy="0 0 0" />
      <geometry>
        <mesh
          filename="package://inspire_hand_description/meshes/right/right_little_force_sensor_1.STL" />
      </geometry>
      <material
        name="">
        <color
          rgba="0.25 0.25 0.25 1" />
      </material>
    </visual>
    <collision>
      <origin
        xyz="0 0 0"
        rpy="0 0 0" />
      <geometry>
        <mesh
          filename="package://inspire_hand_description/meshes/right/right_little_force_sensor_1.STL" />
      </geometry>
    </collision>
  </link>
  <joint
    name="right_little_force_sensor_1_joint"
    type="fixed">
    <origin
      xyz="0.012046 0.019649 0.006651"
      rpy="-1.5708 1.4637 -1.3587" />
    <parent
      link="right_little_1" />
    <child
      link="right_little_force_sensor_1" />
    <axis
      xyz="0 0 0" />
  </joint>
</robot>
